Workbook

Sheet oct17old
A1: M/S XYZ ENTERPRISES GST CALCULATION FOR THE MONTH OF OCT 2017
A2: OUTWARD SUPPLY | B2: 0.05 | E2: 0.12 | H2: 0.18 | K2: 0.28 | N2: CESS
B3: AMT | C3: CGST | D3: SGST | E3: AMT | F3: CGST | G3: SGST | H3: AMT | I3: CGST | J3: SGST | K3: AMT | L3: CGST | M3: SGST | N3: AMT | O3: 0.12
A4: SALES | B4: 0 | C4: =B4*B2/2 -> 0 | D4: =B4*B2/2 -> 0 | F4: =E4*E2/2 -> 0 | G4: =E4*E2/2 -> 0 | H4: 761000 | I4: =H4*H2/2 -> 68490 | J4: =H4*H2/2 -> 68490 | L4: =K4*K2/2 -> 0 | M4: =K4*K2/2 -> 0 | O4: =N4*O3 -> 0
A5: OTHER RECEIPT | C5: =B5*B2/2 -> 0 | D5: =B5*B2/2 -> 0 | F5: =E5*E2/2 -> 0 | G5: =E5*E2/2 -> 0 | I5: =H5*H2/2 -> 0 | J5: =H5*H2/2 -> 0 | L5: =K5*K2/2 -> 0 | M5: =K5*K2/2 -> 0 | O5: =N5*O3 -> 0
A7: INWARD SUPPLY | B7: 0.05 | E7: 0.12 | H7: 0.18 | K7: 0.28 | N7: CESS
B8: AMT | C8: CGST | D8: SGST | E8: AMT | F8: CGST | G8: SGST | H8: AMT | I8: CGST | J8: SGST | K8: AMT | L8: CGST | M8: SGST | N8: AMT | O8: 0.12
A9: PURCHASES | C9: =B9*B7/2 -> 0 | D9: =B9*B7/2 -> 0 | E9: 0 | F9: =E9*E7/2 -> 0 | G9: =E9*E7/2 -> 0 | I9: =H9*H7/2 -> 0 | J9: =H9*H7/2 -> 0 | L9: =K9*K7/2 -> 0 | M9: =K9*K7/2 -> 0 | O9: =N9*O8 -> 0
A10: GST EXPENSES | C10: =B10*B7/2 -> 0 | D10: =B10*B7/2 -> 0 | E10: 0 | F10: =E10*E7/2 -> 0 | G10: =E10*E7/2 -> 0 | I10: =H10*H7/2 -> 0 | J10: =H10*H7/2 -> 0 | L10: =K10*K7/2 -> 0 | M10: =K10*K7/2 -> 0 | O10: =N10*O8 -> 0
A11: RCM | C11: =B11*B7/2 -> 0 | D11: =B11*B7/2 -> 0 | F11: =E11*E7/2 -> 0 | G11: =E11*E7/2 -> 0 | I11: =H11*H7/2 -> 0 | J11: =H11*H7/2 -> 0 | L11: =K11*K7/2 -> 0 | M11: =K11*K7/2 -> 0
A13: IGST OUTWARD SUPPLY | B13: 0.05 | D13: 0.12 | F13: 0.18 | H13: 0.28 | J13: EXEMPT SALES | L13: NON GST SALES
B14: AMT | C14: IGST | D14: AMT | E14: IGST | F14: AMT | G14: IGST | H14: AMT | I14: IGST | J14: AMOUNT | L14: AMOUNT
A15: SALES | C15: =B15*B13 -> 0 | D15: 0 | E15: =D15*D13 -> 0 | F15: 500000 | G15: =F15*F13 -> 90000 | I15: =H15*H13 -> 0
A17: IGST INWARD SUPPLY | B17: 0.05 | D17: 0.12 | F17: 0.18 | H17: 0.28 | J17: EXEMPT PURCHASE | L17: NON GST PURCHASES/URD
B18: AMT | C18: IGST | D18: AMT | E18: IGST | F18: AMT | G18: IGST | H18: AMT | I18: IGST | J18: AMOUNT | L18: AMOUNT
A19: PURCHASE | C19: =B19*B17 -> 0 | D19: 0 | E19: =D19*D17 -> 0 | G19: =F19*F17 -> 0 | I19: =H19*H17 -> 0
A20: GST EXPENSES | C20: =B20*B17 -> 0 | E20: =D20*D17 -> 0 | G20: =F20*F17 -> 0 | I20: =H20*H17 -> 0
A22: PARTICULARS | B22: IGST | C22: CGST | D22: SGST | E22: CESS | G22: PARTICULARS | H22: IGST | I22: CGST | J22: SGST | K22: CESS | L22: L Y YR GP
A23: GST COLLECTED | B23: =+C15+E15+G15+I15 -> 90000 | C23: =+C4+F4+I4+L4+C5+F5+I5+L5 -> 68490 | D23: =+D4+G4+J4+M4+D5+G5+J5+M5 -> 68490 | E23: =+O4 -> 0 | G23: RCM PAYABLE | H23: 0 | I23: =+C11+F11+I11+L11 -> 0 | J23: =+D11+G11+J11+M11 -> 0 | K23: =+O11 -> 0
A24: RCM PAYABLE | C24: =+C11+F11+I11+L11 -> 0 | D24: =+D11+G11+J11+M11 -> 0
A25: ITC CREDIT ON PURCHASES | B25: =C19+E19+G19+I19 -> 0 | C25: =+C9+F9+I9+L9 -> 0 | D25: =+D9+G9+J9+M9 -> 0 | E25: =+O9 -> 0 | G25: TAX FREE | H25: 0.05 | I25: 0.12 | J25: 0.18 | K25: 0.28 | L25: OVERALL
A26: ITC CREDIT ON EXPENSES | B26: =C20+E20+G20+I20 -> 0 | C26: =+C10+F10+I10+L10 -> 0 | D26: =+D10+G10+J10+M10 -> 0 | E26: =+O10 -> 0 | G26: =+-((J19+L19)/(J15+L15)*100)+100 -> #DIV/0! | H26: =-(+B9/B4*100)+100 -> #DIV/0! | I26: =-(+E9/E4*100)+100 -> #DIV/0! | J26: =-(+H9/H4*100)+100 -> 100 | K26: =-(+K9/K4*100)+100 -> #DIV/0! | L26: =-(((B9+E9+H9+K9+N9+B19+D19+F19+H19+J19+L19)/(B4+E4+H4+K4+N4+B15+D15+F15+H15+J15+L15))*100)+100 -> 100
A27: ITC CREDIT ON RCM | B27: =C21+E21+G21+I21 -> 0 | C27: =+C11+F11+I11+L11 -> 0 | D27: =+D11+G11+J11+M11 -> 0 | E27: =+O11 -> 0
A28: PREV CR LEDGER BAL | B28: 0 | G28: TOTAL SALES | H28: =+B4+B5+E4+E5+H4+H5+K4+K5+B15+D15+F15+H15 -> 1261000
A29: PREVIOUS CASH BAL | B29: 0 | C29: 80000 | D29: 881 | G29: TOTAL PURCHASE | H29: =+B9+E9+H9+K9+B19+D19+F19+H19 -> 0
A30: NET PAYABLE/REFUND | B30: =+B23+B24-B25-B26-B27-B28-B29 -> 90000 | C30: =+C23+C24-C25-C26-C27-C28-C29 -> -11510 | D30: =+D23+D24-D25-D26-D27-D28-D29 -> 67609 | E30: =+E23+E24-E25-E26-E27-E28-E29 -> 0
A32: PARTICULARS | B32: IGST | C32: CGST | D32: SGST | E32: CESS | F32: TOTAL | I32: PARTICULARS | J32: GST
A33: FINAL AMOUNT PAYABLE | B33: =IF(B30<=0,0,IF(C29<>0,B30,IF(D29<>0,B30,IF(AND(C30<0,D30<0),MAX(0,B30+C30+D30),IF(AND(C30<0,D30>=0),MAX(0,B30+C30),IF(AND(C30>=0,D30<0),MAX(0,B30+D30),B30)))))) -> 90000 | C33: =IF(C30<=0,0,IF(AND(C30>0,B30<0),MAX(0,C30-B28),C30)) -> 0 | D33: =IF(D30<=0,0,IF(AND(D30>0,B30+C30<0,C30>0),MAX(0,D30+C30+B30),IF(AND(D30>0,B30<0,C30<=0),MAX(0,D30+B30),D30))) -> 67609 | E33: =IF(E30<=0,0,E30) -> 0 | F33: =SUM(B33:E33) -> 157609 | I33: Due Date
A34: RCM FINAL PAYABLE | B34: =+H23 -> 0 | C34: =IF(C33>=I23,0,I23-C33) -> 0 | D34: =IF(D33>=J23,0,J23-D33) -> 0 | E34: =IF(E33>=K23,0,K23-E33) -> 0 | F34: =SUM(B34:E34) -> 0 | I34: Payment
A35: TOTAL PAYABLE | B35: =SUM(B33:B34) -> 90000 | C35: =SUM(C33:C34) -> 0 | D35: =SUM(D33:D34) -> 67609 | E35: =SUM(E33:E34) -> 0 | F35: =SUM(B35:E35) -> 157609 | I35: Delayed Days | J35: =+J34-J33 -> 0
A36: INTEREST PAYABLE | B36: =ROUND((B35*J35/365)*18/100,0) -> 0 | C36: =ROUND((C35*$J$35/365)*18/100,0) -> 0 | D36: =ROUND((D35*$J$35/365)*18/100,0) -> 0 | E36: =ROUND((E35*$J$35/365)*18/100,0) -> 0 | F36: =SUM(B36:E36) -> 0
A37: TOTAL CHALLAN PAYABLE | B37: =+B35+B36 -> 90000 | C37: =+C35+C36 -> 0 | D37: =+D35+D36 -> 67609 | E37: =+E35+E36 -> 0 | F37: =SUMIF(B37:E37,">0") -> 157609

Sheet oct old2 
A1: M/S XYZ ENTERPRISES GST CALCULATION FOR THE MONTH OF OCT 2017
A2: OUTWARD SUPPLY | B2: 0.05 | E2: 0.12 | H2: 0.18 | K2: 0.28 | N2: CESS
B3: AMT | C3: CGST | D3: SGST | E3: AMT | F3: CGST | G3: SGST | H3: AMT | I3: CGST | J3: SGST | K3: AMT | L3: CGST | M3: SGST | N3: AMT | O3: 0.12
A4: SALES | B4: 0 | C4: =B4*B2/2 -> 0 | D4: =B4*B2/2 -> 0 | F4: =E4*E2/2 -> 0 | G4: =E4*E2/2 -> 0 | H4: 761000 | I4: =H4*H2/2 -> 68490 | J4: =H4*H2/2 -> 68490 | L4: =K4*K2/2 -> 0 | M4: =K4*K2/2 -> 0 | O4: =N4*O3 -> 0
A5: OTHER RECEIPT | C5: =B5*B2/2 -> 0 | D5: =B5*B2/2 -> 0 | F5: =E5*E2/2 -> 0 | G5: =E5*E2/2 -> 0 | I5: =H5*H2/2 -> 0 | J5: =H5*H2/2 -> 0 | L5: =K5*K2/2 -> 0 | M5: =K5*K2/2 -> 0 | O5: =N5*O3 -> 0
A7: INWARD SUPPLY | B7: 0.05 | E7: 0.12 | H7: 0.18 | K7: 0.28 | N7: CESS
B8: AMT | C8: CGST | D8: SGST | E8: AMT | F8: CGST | G8: SGST | H8: AMT | I8: CGST | J8: SGST | K8: AMT | L8: CGST | M8: SGST | N8: AMT | O8: 0.12
A9: PURCHASES | C9: =B9*B7/2 -> 0 | D9: =B9*B7/2 -> 0 | E9: 0 | F9: =E9*E7/2 -> 0 | G9: =E9*E7/2 -> 0 | H9: 1000000 | I9: =H9*H7/2 -> 90000 | J9: =H9*H7/2 -> 90000 | L9: =K9*K7/2 -> 0 | M9: =K9*K7/2 -> 0 | O9: =N9*O8 -> 0
A10: GST EXPENSES | C10: =B10*B7/2 -> 0 | D10: =B10*B7/2 -> 0 | E10: 0 | F10: =E10*E7/2 -> 0 | G10: =E10*E7/2 -> 0 | I10: =H10*H7/2 -> 0 | J10: =H10*H7/2 -> 0 | L10: =K10*K7/2 -> 0 | M10: =K10*K7/2 -> 0 | O10: =N10*O8 -> 0
A11: RCM | C11: =B11*B7/2 -> 0 | D11: =B11*B7/2 -> 0 | F11: =E11*E7/2 -> 0 | G11: =E11*E7/2 -> 0 | I11: =H11*H7/2 -> 0 | J11: =H11*H7/2 -> 0 | L11: =K11*K7/2 -> 0 | M11: =K11*K7/2 -> 0
A13: IGST OUTWARD SUPPLY | B13: 0.05 | D13: 0.12 | F13: 0.18 | H13: 0.28 | J13: EXEMPT SALES | L13: NON GST SALES
B14: AMT | C14: IGST | D14: AMT | E14: IGST | F14: AMT | G14: IGST | H14: AMT | I14: IGST | J14: AMOUNT | L14: AMOUNT
A15: SALES | C15: =B15*B13 -> 0 | D15: 0 | E15: =D15*D13 -> 0 | F15: 500000 | G15: =F15*F13 -> 90000 | I15: =H15*H13 -> 0
A17: IGST INWARD SUPPLY | B17: 0.05 | D17: 0.12 | F17: 0.18 | H17: 0.28 | J17: EXEMPT PURCHASE | L17: NON GST PURCHASES/URD
B18: AMT | C18: IGST | D18: AMT | E18: IGST | F18: AMT | G18: IGST | H18: AMT | I18: IGST | J18: AMOUNT | L18: AMOUNT
A19: PURCHASE | C19: =B19*B17 -> 0 | D19: 0 | E19: =D19*D17 -> 0 | G19: =F19*F17 -> 0 | I19: =H19*H17 -> 0
A20: GST EXPENSES | C20: =B20*B17 -> 0 | E20: =D20*D17 -> 0 | G20: =F20*F17 -> 0 | I20: =H20*H17 -> 0
A22: PARTICULARS | B22: IGST | C22: CGST | D22: SGST | E22: CESS | G22: PARTICULARS | H22: IGST | I22: CGST | J22: SGST | K22: CESS | L22: L Y YR GP
A23: GST COLLECTED | B23: =+C15+E15+G15+I15 -> 90000 | C23: =+C4+F4+I4+L4+C5+F5+I5+L5 -> 68490 | D23: =+D4+G4+J4+M4+D5+G5+J5+M5 -> 68490 | E23: =+O4 -> 0 | G23: RCM PAYABLE | H23: 0 | I23: =+C11+F11+I11+L11 -> 0 | J23: =+D11+G11+J11+M11 -> 0 | K23: =+O11 -> 0
A24: RCM PAYABLE | C24: =+C11+F11+I11+L11 -> 0 | D24: =+D11+G11+J11+M11 -> 0
A25: ITC CREDIT ON PURCHASES | B25: =C19+E19+G19+I19 -> 0 | C25: =+C9+F9+I9+L9 -> 90000 | D25: =+D9+G9+J9+M9 -> 90000 | E25: =+O9 -> 0 | G25: TAX FREE | H25: 0.05 | I25: 0.12 | J25: 0.18 | K25: 0.28 | L25: OVERALL
A26: ITC CREDIT ON EXPENSES | B26: =C20+E20+G20+I20 -> 0 | C26: =+C10+F10+I10+L10 -> 0 | D26: =+D10+G10+J10+M10 -> 0 | E26: =+O10 -> 0 | G26: =+-((J19+L19)/(J15+L15)*100)+100 -> #DIV/0! | H26: =-(+B9/B4*100)+100 -> #DIV/0! | I26: =-(+E9/E4*100)+100 -> #DIV/0! | J26: =-(+H9/H4*100)+100 -> -31.406045 | K26: =-(+K9/K4*100)+100 -> #DIV/0! | L26: =-(((B9+E9+H9+K9+N9+B19+D19+F19+H19+J19+L19)/(B4+E4+H4+K4+N4+B15+D15+F15+H15+J15+L15))*100)+100 -> 20.697859
A27: ITC CREDIT ON RCM | B27: =C21+E21+G21+I21 -> 0 | C27: =+C11+F11+I11+L11 -> 0 | D27: =+D11+G11+J11+M11 -> 0 | E27: =+O11 -> 0
A28: PREV CR LEDGER BAL | G28: TOTAL SALES | H28: =+B4+B5+E4+E5+H4+H5+K4+K5+B15+D15+F15+H15 -> 1261000
A29: PREVIOUS CASH BAL | C29: 0 | D29: 0 | G29: TOTAL PURCHASE | H29: =+B9+E9+H9+K9+B19+D19+F19+H19 -> 1000000
A30: NET PAYABLE/REFUND | B30: =+B23+B24-B25-B26-B27-B28-B29 -> 90000 | C30: =+C23+C24-C25-C26-C27-C28-C29 -> -21510 | D30: =+D23+D24-D25-D26-D27-D28-D29 -> -21510 | E30: =+E23+E24-E25-E26-E27-E28-E29 -> 0
A32: PARTICULARS | B32: IGST | C32: CGST | D32: SGST | E32: CESS | F32: TOTAL | I32: PARTICULARS | J32: GST
A33: FINAL AMOUNT PAYABLE | B33: =IF(B30<=0,0,IF(C29<>0,B30+C30+C29+D30+D29,IF(D29<>0,B30,IF(AND(C30<0,D30<0),MAX(0,B30+C30+D30),IF(AND(C30<0,D30>=0),MAX(0,B30+C30),IF(AND(C30>=0,D30<0),MAX(0,B30+D30),B30)))))) -> 46980 | C33: =IF(C30<=0,0,IF(AND(C30>0,B30<0),MAX(0,C30-B28),C30)) -> 0 | D33: =IF(D30<=0,0,IF(AND(D30>0,B30+C30<0,C30>0),MAX(0,D30+C30+B30),IF(AND(D30>0,B30<0,C30<=0),MAX(0,D30+B30),D30))) -> 0 | E33: =IF(E30<=0,0,E30) -> 0 | F33: =SUM(B33:E33) -> 46980 | I33: Due Date
A34: RCM FINAL PAYABLE | B34: =+H23 -> 0 | C34: =IF(C33>=I23,0,I23-C33) -> 0 | D34: =IF(D33>=J23,0,J23-D33) -> 0 | E34: =IF(E33>=K23,0,K23-E33) -> 0 | F34: =SUM(B34:E34) -> 0 | I34: Payment
A35: TOTAL PAYABLE | B35: =SUM(B33:B34) -> 46980 | C35: =SUM(C33:C34) -> 0 | D35: =SUM(D33:D34) -> 0 | E35: =SUM(E33:E34) -> 0 | F35: =SUM(B35:E35) -> 46980 | I35: Delayed Days | J35: =+J34-J33 -> 0
A36: INTEREST PAYABLE | B36: =ROUND((B35*J35/365)*18/100,0) -> 0 | C36: =ROUND((C35*$J$35/365)*18/100,0) -> 0 | D36: =ROUND((D35*$J$35/365)*18/100,0) -> 0 | E36: =ROUND((E35*$J$35/365)*18/100,0) -> 0 | F36: =SUM(B36:E36) -> 0
A37: TOTAL CHALLAN PAYABLE | B37: =+B35+B36 -> 46980 | C37: =+C35+C36 -> 0 | D37: =+D35+D36 -> 0 | E37: =+E35+E36 -> 0 | F37: =SUMIF(B37:E37,">0") -> 46980

Sheet APR-25
A1: SPACE HOME GST CALCULATION FOR THE MONTH OF APRIL 2025
A2: OUTWARD SUPPLY | B2: 0.01 | E2: 0.05 | H2: 0.18 | K2: 0.28 | N2: CESS
B3: AMT | C3: CGST | D3: SGST | E3: AMT | F3: CGST | G3: SGST | H3: AMT | I3: CGST | J3: SGST | K3: AMT | L3: CGST | M3: SGST | N3: AMT | O3: 0.12
A4: SALES | C4: =B4*B2/2 -> 0 | D4: =B4*B2/2 -> 0 | E4: ='APR-25 WORKING'!H8 -> 7800000 | F4: =E4*E2/2 -> 195000 | G4: =E4*E2/2 -> 195000 | L4: =K4*K2/2 -> 0 | M4: =K4*K2/2 -> 0 | O4: =N4*O3 -> 0
A5: ADVANCE | B5: =#REF! -> #REF! | C5: 0 | D5: 0 | E5: ='APR-25 WORKING'!F13 -> 400000 | F5: =E5*E2/2 -> 10000 | G5: =E5*E2/2 -> 10000 | L5: =K5*K2/2 -> 0 | M5: =K5*K2/2 -> 0 | O5: =N5*O3 -> 0
A7: INWARD SUPPLY | B7: 0.05 | E7: 0.12 | H7: 0.18 | K7: 0.28 | N7: CESS
B8: AMT | C8: CGST | D8: SGST | E8: AMT | F8: CGST | G8: SGST | H8: AMT | I8: CGST | J8: SGST | K8: AMT | L8: CGST | M8: SGST | N8: AMT | O8: 0.12
A9: PURCHASES | C9: =B9*B7/2 -> 0 | D9: =B9*B7/2 -> 0 | F9: =E9*E7/2 -> 0 | G9: =E9*E7/2 -> 0 | I9: =H9*H7/2 -> 0 | J9: =I9 -> 0 | L9: =K9*K7/2 -> 0 | M9: =K9*K7/2 -> 0 | O9: =N9*O8 -> 0
A10: REVERSE | C10: =B10*B7/2 -> 0 | D10: =B10*B7/2 -> 0 | G10: =F10 -> 0 | I10: =H10*H7/2 -> 0 | J10: =+I10 -> 0 | L10: =K10*K7/2 -> 0 | M10: =K10*K7/2 -> 0 | O10: =N10*O8 -> 0
A11: RCM | C11: =B11*B7/2 -> 0 | D11: =B11*B7/2 -> 0 | F11: =E11*E7/2 -> 0 | G11: =E11*E7/2 -> 0 | I11: =H11*H7/2 -> 0 | J11: =H11*H7/2 -> 0 | L11: =K11*K7/2 -> 0 | M11: =L11 -> 0
A13: IGST OUTWARD SUPPLY | B13: 0.05 | D13: 0.12 | F13: 0.18 | H13: 0.28 | J13: EXEMPT SALES | L13: NON GST SALES
B14: AMT | C14: IGST | D14: AMT | E14: IGST | F14: AMT | G14: IGST | H14: AMT | I14: IGST | J14: AMOUNT | L14: AMOUNT
A15: SALES | C15: =B15*B13 -> 0 | D15: 0 | E15: =D15*D13 -> 0 | I15: =H15*H13 -> 0
A17: IGST INWARD SUPPLY | B17: 0.05 | D17: 0.12 | F17: 0.18 | H17: 0.28 | J17: EXEMPT PURCHASE | L17: NON GST PURCHASES/URD
B18: AMT | C18: IGST | D18: AMT | E18: IGST | F18: AMT | G18: IGST | H18: AMT | I18: IGST | J18: AMOUNT | L18: AMOUNT
A19: PURCHASE- AUG.22 | B19: 0 | C19: =B19*B17 -> 0 | D19: 0 | E19: =D19*D17 -> 0 | G19: =F19*F17 -> 0 | I19: =H19*H17 -> 0
A20: PURCHASES AUG.22 | C20: =B20*B17 -> 0 | E20: =D20*D17 -> 0 | F20: 0 | G20: =F20*F17 -> 0 | H20: 0 | I20: =H20*H17 -> 0
A22: PARTICULARS | B22: IGST | C22: CGST | D22: SGST | E22: CESS | G22: PARTICULARS | H22: IGST | I22: CGST | J22: SGST | K22: CESS | L22: L Y YR GP
A23: GST COLLECTED | B23: =+C15+E15+G15+I15 -> 0 | C23: =+C4+F4+I4+L4+C5+F5+I5+L5 -> 205000 | D23: =+D4+G4+J4+M4+D5+G5+J5+M5 -> 205000 | E23: =+O4 -> 0 | G23: RCM PAYABLE | H23: 0 | I23: =+C11+F11+I11+L11 -> 0 | J23: =+D11+G11+J11+M11 -> 0 | K23: =+O11 -> 0
A24: RCM PAYABLE | C24: =+C11+F11+I11+L11 -> 0 | D24: =+D11+G11+J11+M11 -> 0
A25: ITC CREDIT ON PURCHASES | B25: =C19+E19+G19+I19 -> 0 | C25: =+C9+F9+I9+L9 -> 0 | D25: =+D9+G9+J9+M9 -> 0 | E25: =+O9 -> 0 | G25: TAX FREE | H25: 0.05 | I25: 0.12 | J25: 0.18 | K25: 0.28 | L25: OVERALL
A26: ITC CREDIT ON EXPENSES | B26: =C20+E20+G20+I20 -> 0 | C26: =+C10+F10+I10+L10 -> 0 | D26: =+D10+G10+J10+M10 -> 0 | E26: =+O10 -> 0 | G26: =+-((J19+L19)/(J15+L15)*100)+100 -> #DIV/0! | H26: =-(+B9/B4*100)+100 -> #DIV/0! | I26: =-(+E9/E4*100)+100 -> 100 | J26: =-(+H9/H4*100)+100 -> #DIV/0! | K26: =-(+K9/K4*100)+100 -> #DIV/0! | L26: =-(((B9+E9+H9+K9+N9+B19+D19+F19+H19+J19+L19)/(B4+E4+H4+K4+N4+B15+D15+F15+H15+J15+L15))*100)+100 -> 100
A27: ITC CREDIT ON RCM | B27: =C21+E21+G21+I21 -> 0 | C27: =+C11+F11+I11+L11 -> 0 | D27: =+D11+G11+J11+M11 -> 0 | E27: =+O11 -> 0 | H27: TAXABLE | I27: TOTAL
A28: PREV CR LEDGER BAL | G28: TOTAL SALES | H28: =+B4+B5+E4+E5+H4+H5+K4+K5+B15+D15+F15+H15 -> #REF! | I28: =+H28+J15+L15 -> #REF!
A29: PREVIOUS CASH BAL | B29: 0 | G29: TOTAL PURCHASE | H29: =+B9+E9+H9+K9+B19+D19+F19+H19 -> 0
A30: NET PAYABLE/REFUND | B30: =+B23+B24-B25-B26-B27-B28-B29 -> 0 | C30: =+C23+C24-C25-C26-C27-C28-C29 -> 205000 | D30: =+D23+D24-D25-D26-D27-D28-D29 -> 205000 | E30: =+E23+E24-E25-E26-E27-E28-E29 -> 0 | F30: =B30+C30+D30 -> 410000
A32: PARTICULARS | B32: IGST | C32: CGST | D32: SGST | E32: CESS | F32: TOTAL | I32: PARTICULARS | J32: GST
A33: FINAL AMOUNT PAYABLE | B33: =IF(B30<=0,0,IF(AND(C30+C29>0,D30+D29>0),B30,IF(C30+C29>0,MAX(0,B30+D30+D29),IF(D30+D29>0,MAX(0,B30+C30+C29),IF(AND(C29<>0,C30<0,D30<0),MAX(0,B30+C30+C29+D30+D29),IF(AND(C29<>0,C30<0),MAX(0,B30+C30+C29),IF(D29<>0,MAX(0,B30+C30+C29+D30+D29),IF(AND(C30<0,D30<0),MAX(0,B30+C30+D30),IF(AND(C30<0,D30>=0),MAX(0,B30+C30),IF(AND(C30>=0,D30<0),MAX(0,B30+D30),B30)))))))))) -> 0 | C33: =IF(C30<=0,0,IF(B30+B29>=0,C30,IF(AND(C30>0,B30<0),MAX(0,C30+B30+B29),C30))) -> 205000 | D33: =IF(D30<=0,0,IF(B30+B29>=0,D30,IF(AND(D30>0,B30+C30+B29<0,C30>0),MAX(0,D30+C30+B30+B29),IF(AND(D30>0,B30<0,C30<=0),MAX(0,D30+B30+B29),D30)))) -> 205000 | E33: =IF(E30<=0,0,E30) -> 0 | F33: =SUM(B33:E33) -> 410000 | I33: Due Date | J33: 45402
A34: RCM FINAL PAYABLE | B34: =+H23 -> 0 | C34: =IF(C33>=I23,0,I23-C33) -> 0 | D34: =IF(D33>=J23,0,J23-D33) -> 0 | E34: =IF(E33>=K23,0,K23-E33) -> 0 | F34: =SUM(B34:E34) -> 0 | I34: Payment | J34: 45402
A35: TOTAL PAYABLE | B35: =SUM(B33:B34) -> 0 | C35: =SUM(C33:C34) -> 205000 | D35: =SUM(D33:D34) -> 205000 | E35: =SUM(E33:E34) -> 0 | F35: =SUM(B35:E35) -> 410000 | I35: Delayed Days | J35: =J34-J33 -> 0
A36: INTEREST PAYABLE | B36: =ROUND((B35*J35/365)*18/100,0) -> 0 | C36: =ROUND((C35*$J$35/365)*18/100,0) -> 0 | D36: =ROUND((D35*$J$35/365)*18/100,0) -> 0 | E36: =ROUND((E35*$J$35/365)*18/100,0) -> 0 | F36: =SUM(B36:E36) -> 0 | I36: LATE FESS | J36: =J35*50 -> 0
A37: TOTAL CHALLAN PAYABLE | B37: =+B35+B36 -> 0 | C37: =+C35+C36 -> 205000 | D37: =+D35+D36 -> 205000 | E37: =+E35+E36 -> 0 | F37: =SUMIF(B37:E37,">0") -> 410000 | I37: TOTAL | J37: =F37+J36 -> 410000

Sheet APR-25 WORKING
E1: MARCH 2025 GST CALCULATION
C2: (NOTE: IF AGREEMENT VALUE CROSS MORE THAN 45,00,000 THEN GST 5% APPLY)
A3: DATE | B3: FLAT NO. | C3: AGREEMENT DONE | D3: AGREEMENT AMOUNT | E3: GST | F3: ADVANCES AMOUNT | G3: REVERSE GST ON ADVANCE | H3: OUTSTANDINGN AMOUNT | I3: OUTSTANDING GST
B4: 606 | C4: PRAJAKTA & SAGAR VARTAK | D4: 8000000 | E4: =D4*5% -> 400000 | F4: 200000 | G4: =F4*5% -> 10000 | H4: =D4-F4 -> 7800000 | I4: =H4*5% -> 390000
E5: =D5*5% -> 0 | H5: =D5-F5 -> 0 | I5: =H5*5% -> 0
E6: =D6*5% -> 0 | H6: =D6-F6 -> 0 | I6: =H6*5% -> 0
D8: =SUM(D4:D6) -> 8000000 | E8: =SUM(E4:E6) -> 400000 | F8: =SUM(F4:F6) -> 200000 | G8: =SUM(G4:G6) -> 10000 | H8: =SUM(H4:H6) -> 7800000 | I8: =SUM(I4:I6) -> 390000
B11: CALCULATION ON ADVANCES
A12: DATE | B12: FLAT NO | C12: NAME | D12: ADVANCE AMOUNT 1 % | E12: 1% GST | F12: ADVANCE AMOUNT 5% | G12: 5% GST
A13: 45773 | B13: 508 | C13: LUCAS CASTELLINO | E13: =D13*1% -> 0 | F13: 400000 | G13: =F13*5% -> 20000
E14: =D14*1% -> 0 | G14: =F14*5% -> 0
E15: =D15*1% -> 0 | G15: =F15*5% -> 0
E16: =D16*1% -> 0 | G16: =F16*5% -> 0
E17: =D17*1% -> 0 | G17: =F17*5% -> 0
C18: TOTAL | D18: =SUM(D13:D17) -> 0 | E18: =D18*1% -> 0 | F18: =SUM(F13:F17) -> 400000 | G18: =SUM(G13:G17) -> 20000 | H18: TOTAL PAYABLE | I18: =ROUND(I8+E18+G18,0) -> 410000

Sheet MAY-25
A1: SPACE HOME GST CALCULATION FOR THE MONTH OF APRIL 2025
A2: OUTWARD SUPPLY | B2: 0.01 | E2: 0.05 | H2: 0.18 | K2: 0.28 | N2: CESS
B3: AMT | C3: CGST | D3: SGST | E3: AMT | F3: CGST | G3: SGST | H3: AMT | I3: CGST | J3: SGST | K3: AMT | L3: CGST | M3: SGST | N3: AMT | O3: 0.12
A4: SALES | B4: ='MAY-25 WORKING'!H6 -> 4488000 | C4: =B4*B2/2 -> 22440 | D4: =B4*B2/2 -> 22440 | E4: =SUM('MAY-25 WORKING'!H4:H5) -> 14400000 | F4: =E4*E2/2 -> 360000 | G4: =E4*E2/2 -> 360000 | L4: =K4*K2/2 -> 0 | M4: =K4*K2/2 -> 0 | O4: =N4*O3 -> 0
A5: ADVANCE | B5: 0 | C5: 0 | D5: 0 | E5: ='MAY-25 WORKING'!F18 -> 0 | F5: =E5*E2/2 -> 0 | G5: =E5*E2/2 -> 0 | L5: =K5*K2/2 -> 0 | M5: =K5*K2/2 -> 0 | O5: =N5*O3 -> 0
A7: INWARD SUPPLY | B7: 0.05 | E7: 0.12 | H7: 0.18 | K7: 0.28 | N7: CESS
B8: AMT | C8: CGST | D8: SGST | E8: AMT | F8: CGST | G8: SGST | H8: AMT | I8: CGST | J8: SGST | K8: AMT | L8: CGST | M8: SGST | N8: AMT | O8: 0.12
A9: PURCHASES | C9: =B9*B7/2 -> 0 | D9: =B9*B7/2 -> 0 | F9: =E9*E7/2 -> 0 | G9: =E9*E7/2 -> 0 | I9: =H9*H7/2 -> 0 | J9: =I9 -> 0 | L9: =K9*K7/2 -> 0 | M9: =K9*K7/2 -> 0 | O9: =N9*O8 -> 0
A10: REVERSE | C10: =B10*B7/2 -> 0 | D10: =B10*B7/2 -> 0 | G10: =F10 -> 0 | I10: =H10*H7/2 -> 0 | J10: =+I10 -> 0 | L10: =K10*K7/2 -> 0 | M10: =K10*K7/2 -> 0 | O10: =N10*O8 -> 0
A11: RCM | C11: =B11*B7/2 -> 0 | D11: =B11*B7/2 -> 0 | F11: =E11*E7/2 -> 0 | G11: =E11*E7/2 -> 0 | I11: =H11*H7/2 -> 0 | J11: =H11*H7/2 -> 0 | L11: =K11*K7/2 -> 0 | M11: =L11 -> 0
A13: IGST OUTWARD SUPPLY | B13: 0.05 | D13: 0.12 | F13: 0.18 | H13: 0.28 | J13: EXEMPT SALES | L13: NON GST SALES
B14: AMT | C14: IGST | D14: AMT | E14: IGST | F14: AMT | G14: IGST | H14: AMT | I14: IGST | J14: AMOUNT | L14: AMOUNT
A15: SALES | C15: =B15*B13 -> 0 | D15: 0 | E15: =D15*D13 -> 0 | I15: =H15*H13 -> 0
A17: IGST INWARD SUPPLY | B17: 0.05 | D17: 0.12 | F17: 0.18 | H17: 0.28 | J17: EXEMPT PURCHASE | L17: NON GST PURCHASES/URD
B18: AMT | C18: IGST | D18: AMT | E18: IGST | F18: AMT | G18: IGST | H18: AMT | I18: IGST | J18: AMOUNT | L18: AMOUNT
A19: PURCHASE- AUG.22 | B19: 0 | C19: =B19*B17 -> 0 | D19: 0 | E19: =D19*D17 -> 0 | G19: =F19*F17 -> 0 | I19: =H19*H17 -> 0
A20: PURCHASES AUG.22 | C20: =B20*B17 -> 0 | E20: =D20*D17 -> 0 | F20: 0 | G20: =F20*F17 -> 0 | H20: 0 | I20: =H20*H17 -> 0
A22: PARTICULARS | B22: IGST | C22: CGST | D22: SGST | E22: CESS | G22: PARTICULARS | H22: IGST | I22: CGST | J22: SGST | K22: CESS | L22: L Y YR GP
A23: GST COLLECTED | B23: =+C15+E15+G15+I15 -> 0 | C23: =+C4+F4+I4+L4+C5+F5+I5+L5 -> 382440 | D23: =+D4+G4+J4+M4+D5+G5+J5+M5 -> 382440 | E23: =+O4 -> 0 | G23: RCM PAYABLE | H23: 0 | I23: =+C11+F11+I11+L11 -> 0 | J23: =+D11+G11+J11+M11 -> 0 | K23: =+O11 -> 0
A24: RCM PAYABLE | C24: =+C11+F11+I11+L11 -> 0 | D24: =+D11+G11+J11+M11 -> 0
A25: ITC CREDIT ON PURCHASES | B25: =C19+E19+G19+I19 -> 0 | C25: =+C9+F9+I9+L9 -> 0 | D25: =+D9+G9+J9+M9 -> 0 | E25: =+O9 -> 0 | G25: TAX FREE | H25: 0.05 | I25: 0.12 | J25: 0.18 | K25: 0.28 | L25: OVERALL
A26: ITC CREDIT ON EXPENSES | B26: =C20+E20+G20+I20 -> 0 | C26: =+C10+F10+I10+L10 -> 0 | D26: =+D10+G10+J10+M10 -> 0 | E26: =+O10 -> 0 | G26: =+-((J19+L19)/(J15+L15)*100)+100 -> #DIV/0! | H26: =-(+B9/B4*100)+100 -> 100 | I26: =-(+E9/E4*100)+100 -> 100 | J26: =-(+H9/H4*100)+100 -> #DIV/0! | K26: =-(+K9/K4*100)+100 -> #DIV/0! | L26: =-(((B9+E9+H9+K9+N9+B19+D19+F19+H19+J19+L19)/(B4+E4+H4+K4+N4+B15+D15+F15+H15+J15+L15))*100)+100 -> 100
A27: ITC CREDIT ON RCM | B27: =C21+E21+G21+I21 -> 0 | C27: =+C11+F11+I11+L11 -> 0 | D27: =+D11+G11+J11+M11 -> 0 | E27: =+O11 -> 0 | H27: TAXABLE | I27: TOTAL
A28: PREV CR LEDGER BAL | G28: TOTAL SALES | H28: =+B4+B5+E4+E5+H4+H5+K4+K5+B15+D15+F15+H15 -> 18888000 | I28: =+H28+J15+L15 -> 18888000
A29: PREVIOUS CASH BAL | B29: 0 | C29: 62000 | D29: 62000 | G29: TOTAL PURCHASE | H29: =+B9+E9+H9+K9+B19+D19+F19+H19 -> 0
A30: NET PAYABLE/REFUND | B30: =+B23+B24-B25-B26-B27-B28-B29 -> 0 | C30: =+C23+C24-C25-C26-C27-C28-C29 -> 320440 | D30: =+D23+D24-D25-D26-D27-D28-D29 -> 320440 | E30: =+E23+E24-E25-E26-E27-E28-E29 -> 0 | F30: =B30+C30+D30 -> 640880
A32: PARTICULARS | B32: IGST | C32: CGST | D32: SGST | E32: CESS | F32: TOTAL | I32: PARTICULARS | J32: GST
A33: FINAL AMOUNT PAYABLE | B33: =IF(B30<=0,0,IF(AND(C30+C29>0,D30+D29>0),B30,IF(C30+C29>0,MAX(0,B30+D30+D29),IF(D30+D29>0,MAX(0,B30+C30+C29),IF(AND(C29<>0,C30<0,D30<0),MAX(0,B30+C30+C29+D30+D29),IF(AND(C29<>0,C30<0),MAX(0,B30+C30+C29),IF(D29<>0,MAX(0,B30+C30+C29+D30+D29),IF(AND(C30<0,D30<0),MAX(0,B30+C30+D30),IF(AND(C30<0,D30>=0),MAX(0,B30+C30),IF(AND(C30>=0,D30<0),MAX(0,B30+D30),B30)))))))))) -> 0 | C33: =IF(C30<=0,0,IF(B30+B29>=0,C30,IF(AND(C30>0,B30<0),MAX(0,C30+B30+B29),C30))) -> 320440 | D33: =IF(D30<=0,0,IF(B30+B29>=0,D30,IF(AND(D30>0,B30+C30+B29<0,C30>0),MAX(0,D30+C30+B30+B29),IF(AND(D30>0,B30<0,C30<=0),MAX(0,D30+B30+B29),D30)))) -> 320440 | E33: =IF(E30<=0,0,E30) -> 0 | F33: =SUM(B33:E33) -> 640880 | I33: Due Date | J33: 45402
A34: RCM FINAL PAYABLE | B34: =+H23 -> 0 | C34: =IF(C33>=I23,0,I23-C33) -> 0 | D34: =IF(D33>=J23,0,J23-D33) -> 0 | E34: =IF(E33>=K23,0,K23-E33) -> 0 | F34: =SUM(B34:E34) -> 0 | I34: Payment | J34: 45402
A35: TOTAL PAYABLE | B35: =SUM(B33:B34) -> 0 | C35: =SUM(C33:C34) -> 320440 | D35: =SUM(D33:D34) -> 320440 | E35: =SUM(E33:E34) -> 0 | F35: =SUM(B35:E35) -> 640880 | I35: Delayed Days | J35: =J34-J33 -> 0
A36: INTEREST PAYABLE | B36: =ROUND((B35*J35/365)*18/100,0) -> 0 | C36: =ROUND((C35*$J$35/365)*18/100,0) -> 0 | D36: =ROUND((D35*$J$35/365)*18/100,0) -> 0 | E36: =ROUND((E35*$J$35/365)*18/100,0) -> 0 | F36: =SUM(B36:E36) -> 0 | I36: LATE FESS | J36: =J35*50 -> 0
A37: TOTAL CHALLAN PAYABLE | B37: =+B35+B36 -> 0 | C37: =+C35+C36 -> 320440 | D37: =+D35+D36 -> 320440 | E37: =+E35+E36 -> 0 | F37: =SUMIF(B37:E37,">0") -> 640880 | I37: TOTAL | J37: =F37+J36 -> 640880

Sheet MAY-25 WORKING
E1: MAY 2025 GST CALCULATION
C2: (NOTE: IF AGREEMENT VALUE CROSS MORE THAN 45,00,000 THEN GST 5% APPLY)
A3: DATE | B3: FLAT NO. | C3: AGREEMENT DONE | D3: AGREEMENT AMOUNT | E3: GST | F3: ADVANCES AMOUNT | G3: REVERSE GST ON ADVANCE | H3: OUTSTANDINGN AMOUNT | I3: OUTSTANDING GST
B4: 806 | C4: SHWETA FERNANDES | D4: 7500000 | E4: =D4*5% -> 375000 | F4: 1500000 | G4: =F4*5% -> 75000 | H4: =D4-F4 -> 6000000 | I4: =H4*5% -> 300000
B5: 309 | C5: IRWIN KENNATH KARKADA | D5: 8400000 | E5: =D5*5% -> 420000 | H5: =D5-F5 -> 8400000 | I5: =H5*5% -> 420000
B6: 1409 | C6: AMEYA TOWNHOMES PVT.LTD (Landowner) | D6: 4488000 | E6: =D6*1% -> 44880 | H6: =D6-F6 -> 4488000 | I6: =H6*1% -> 44880
D8: =SUM(D4:D6) -> 20388000 | E8: =SUM(E4:E6) -> 839880 | F8: =SUM(F4:F6) -> 1500000 | G8: =SUM(G4:G6) -> 75000 | H8: =SUM(H4:H6) -> 18888000 | I8: =SUM(I4:I6) -> 764880
B11: CALCULATION ON ADVANCES
A12: DATE | B12: FLAT NO | C12: NAME | D12: ADVANCE AMOUNT 1 % | E12: 1% GST | F12: ADVANCE AMOUNT 5% | G12: 5% GST
E13: =D13*1% -> 0 | G13: =F13*5% -> 0
E14: =D14*1% -> 0 | G14: =F14*5% -> 0
E15: =D15*1% -> 0 | G15: =F15*5% -> 0
E16: =D16*1% -> 0 | G16: =F16*5% -> 0
E17: =D17*1% -> 0 | G17: =F17*5% -> 0
C18: TOTAL | D18: =SUM(D13:D17) -> 0 | E18: =D18*1% -> 0 | F18: =SUM(F13:F17) -> 0 | G18: =SUM(G13:G17) -> 0 | H18: TOTAL PAYABLE | I18: =ROUND(I8+E18+G18,0) -> 764880

Sheet Sheet1
B1: IGST | C1: CGST | D1: SGST | E1: PAYABLE
A2: SALES | B2: 0 | C2: 205000 | D2: 205000 | E2: =SUM(B2:D2) -> 410000
A3: ITC | B3: 0 | C3: 0 | D3: 0 | E3: =SUM(B3:D3) -> 0
A4: CASH LEDGER | B4: 0 | C4: 12696 | D4: 12696 | E4: =SUM(B4:D4) -> 25392
A5: TOTAL | B5: =B2-B3-B4 -> 0 | C5: =C2-C3-C4 -> 192304 | D5: =D2-D3-D4 -> 192304 | E5: =SUM(B5:D5) -> 384608

Sheet JUne-25
A1: SPACE HOME GST CALCULATION FOR THE MONTH OF APRIL 2025
A2: OUTWARD SUPPLY | B2: 0.01 | E2: 0.05 | H2: 0.18 | K2: 0.28 | N2: CESS
B3: AMT | C3: CGST | D3: SGST | E3: AMT | F3: CGST | G3: SGST | H3: AMT | I3: CGST | J3: SGST | K3: AMT | L3: CGST | M3: SGST | N3: AMT | O3: 0.12
A4: SALES | B4: =+'JUNe Working'!D5 -> 4400000 | C4: =B4*B2/2 -> 22000 | D4: =B4*B2/2 -> 22000 | E4: =+'JUNe Working'!D4-'JUNe Working'!G4 -> 4000000 | F4: =E4*E2/2 -> 100000 | G4: =E4*E2/2 -> 100000 | L4: =K4*K2/2 -> 0 | M4: =K4*K2/2 -> 0 | O4: =N4*O3 -> 0
A5: ADVANCE | B5: 0 | C5: 0 | D5: 0 | E5: =+'JUNe Working'!D13 -> 150000 | F5: =E5*E2/2 -> 3750 | G5: =E5*E2/2 -> 3750 | L5: =K5*K2/2 -> 0 | M5: =K5*K2/2 -> 0 | O5: =N5*O3 -> 0
A7: INWARD SUPPLY | B7: 0.05 | E7: 0.12 | H7: 0.18 | K7: 0.28 | N7: CESS
B8: AMT | C8: CGST | D8: SGST | E8: AMT | F8: CGST | G8: SGST | H8: AMT | I8: CGST | J8: SGST | K8: AMT | L8: CGST | M8: SGST | N8: AMT | O8: 0.12
A9: PURCHASES | C9: =B9*B7/2 -> 0 | D9: =B9*B7/2 -> 0 | F9: =E9*E7/2 -> 0 | G9: =E9*E7/2 -> 0 | I9: =H9*H7/2 -> 0 | J9: =I9 -> 0 | L9: =K9*K7/2 -> 0 | M9: =K9*K7/2 -> 0 | O9: =N9*O8 -> 0
A10: REVERSE | C10: =B10*B7/2 -> 0 | D10: =B10*B7/2 -> 0 | G10: =F10 -> 0 | I10: =H10*H7/2 -> 0 | J10: =+I10 -> 0 | L10: =K10*K7/2 -> 0 | M10: =K10*K7/2 -> 0 | O10: =N10*O8 -> 0
A11: RCM | C11: =B11*B7/2 -> 0 | D11: =B11*B7/2 -> 0 | F11: =E11*E7/2 -> 0 | G11: =E11*E7/2 -> 0 | I11: =H11*H7/2 -> 0 | J11: =H11*H7/2 -> 0 | L11: =K11*K7/2 -> 0 | M11: =L11 -> 0
A13: IGST OUTWARD SUPPLY | B13: 0.05 | D13: 0.12 | F13: 0.18 | H13: 0.28 | J13: EXEMPT SALES | L13: NON GST SALES
B14: AMT | C14: IGST | D14: AMT | E14: IGST | F14: AMT | G14: IGST | H14: AMT | I14: IGST | J14: AMOUNT | L14: AMOUNT
A15: SALES | C15: =B15*B13 -> 0 | D15: 0 | E15: =D15*D13 -> 0 | I15: =H15*H13 -> 0
A17: IGST INWARD SUPPLY | B17: 0.05 | D17: 0.12 | F17: 0.18 | H17: 0.28 | J17: EXEMPT PURCHASE | L17: NON GST PURCHASES/URD
B18: AMT | C18: IGST | D18: AMT | E18: IGST | F18: AMT | G18: IGST | H18: AMT | I18: IGST | J18: AMOUNT | L18: AMOUNT
A19: PURCHASE- AUG.22 | B19: 0 | C19: =B19*B17 -> 0 | D19: 0 | E19: =D19*D17 -> 0 | G19: =F19*F17 -> 0 | I19: =H19*H17 -> 0
A20: PURCHASES AUG.22 | C20: =B20*B17 -> 0 | E20: =D20*D17 -> 0 | F20: 0 | G20: =F20*F17 -> 0 | H20: 0 | I20: =H20*H17 -> 0
A22: PARTICULARS | B22: IGST | C22: CGST | D22: SGST | E22: CESS | G22: PARTICULARS | H22: IGST | I22: CGST | J22: SGST | K22: CESS | L22: L Y YR GP
A23: GST COLLECTED | B23: =+C15+E15+G15+I15 -> 0 | C23: =+C4+F4+I4+L4+C5+F5+I5+L5 -> 125750 | D23: =+D4+G4+J4+M4+D5+G5+J5+M5 -> 125750 | E23: =+O4 -> 0 | G23: RCM PAYABLE | H23: 0 | I23: =+C11+F11+I11+L11 -> 0 | J23: =+D11+G11+J11+M11 -> 0 | K23: =+O11 -> 0
A24: RCM PAYABLE | C24: =+C11+F11+I11+L11 -> 0 | D24: =+D11+G11+J11+M11 -> 0
A25: ITC CREDIT ON PURCHASES | B25: =C19+E19+G19+I19 -> 0 | C25: =+C9+F9+I9+L9 -> 0 | D25: =+D9+G9+J9+M9 -> 0 | E25: =+O9 -> 0 | G25: TAX FREE | H25: 0.05 | I25: 0.12 | J25: 0.18 | K25: 0.28 | L25: OVERALL
A26: ITC CREDIT ON EXPENSES | B26: =C20+E20+G20+I20 -> 0 | C26: =+C10+F10+I10+L10 -> 0 | D26: =+D10+G10+J10+M10 -> 0 | E26: =+O10 -> 0 | G26: =+-((J19+L19)/(J15+L15)*100)+100 -> #DIV/0! | H26: =-(+B9/B4*100)+100 -> 100 | I26: =-(+E9/E4*100)+100 -> 100 | J26: =-(+H9/H4*100)+100 -> #DIV/0! | K26: =-(+K9/K4*100)+100 -> #DIV/0! | L26: =-(((B9+E9+H9+K9+N9+B19+D19+F19+H19+J19+L19)/(B4+E4+H4+K4+N4+B15+D15+F15+H15+J15+L15))*100)+100 -> 100
A27: ITC CREDIT ON RCM | B27: =C21+E21+G21+I21 -> 0 | C27: =+C11+F11+I11+L11 -> 0 | D27: =+D11+G11+J11+M11 -> 0 | E27: =+O11 -> 0 | H27: TAXABLE | I27: TOTAL
A28: PREV CR LEDGER BAL | G28: TOTAL SALES | H28: =+B4+B5+E4+E5+H4+H5+K4+K5+B15+D15+F15+H15 -> 8550000 | I28: =+H28+J15+L15 -> 8550000
A29: PREVIOUS CASH BAL | B29: 0 | C29: 696 | D29: 600 | G29: TOTAL PURCHASE | H29: =+B9+E9+H9+K9+B19+D19+F19+H19 -> 0
A30: NET PAYABLE/REFUND | B30: =+B23+B24-B25-B26-B27-B28-B29 -> 0 | C30: =+C23+C24-C25-C26-C27-C28-C29 -> 125054 | D30: =+D23+D24-D25-D26-D27-D28-D29 -> 125150 | E30: =+E23+E24-E25-E26-E27-E28-E29 -> 0 | F30: =B30+C30+D30 -> 250204
A32: PARTICULARS | B32: IGST | C32: CGST | D32: SGST | E32: CESS | F32: TOTAL | I32: PARTICULARS | J32: GST
A33: FINAL AMOUNT PAYABLE | B33: =IF(B30<=0,0,IF(AND(C30+C29>0,D30+D29>0),B30,IF(C30+C29>0,MAX(0,B30+D30+D29),IF(D30+D29>0,MAX(0,B30+C30+C29),IF(AND(C29<>0,C30<0,D30<0),MAX(0,B30+C30+C29+D30+D29),IF(AND(C29<>0,C30<0),MAX(0,B30+C30+C29),IF(D29<>0,MAX(0,B30+C30+C29+D30+D29),IF(AND(C30<0,D30<0),MAX(0,B30+C30+D30),IF(AND(C30<0,D30>=0),MAX(0,B30+C30),IF(AND(C30>=0,D30<0),MAX(0,B30+D30),B30)))))))))) -> 0 | C33: =IF(C30<=0,0,IF(B30+B29>=0,C30,IF(AND(C30>0,B30<0),MAX(0,C30+B30+B29),C30))) -> 125054 | D33: =IF(D30<=0,0,IF(B30+B29>=0,D30,IF(AND(D30>0,B30+C30+B29<0,C30>0),MAX(0,D30+C30+B30+B29),IF(AND(D30>0,B30<0,C30<=0),MAX(0,D30+B30+B29),D30)))) -> 125150 | E33: =IF(E30<=0,0,E30) -> 0 | F33: =SUM(B33:E33) -> 250204 | I33: Due Date | J33: 45402
A34: RCM FINAL PAYABLE | B34: =+H23 -> 0 | C34: =IF(C33>=I23,0,I23-C33) -> 0 | D34: =IF(D33>=J23,0,J23-D33) -> 0 | E34: =IF(E33>=K23,0,K23-E33) -> 0 | F34: =SUM(B34:E34) -> 0 | I34: Payment | J34: 45402
A35: TOTAL PAYABLE | B35: =SUM(B33:B34) -> 0 | C35: =SUM(C33:C34) -> 125054 | D35: =SUM(D33:D34) -> 125150 | E35: =SUM(E33:E34) -> 0 | F35: =SUM(B35:E35) -> 250204 | I35: Delayed Days | J35: =J34-J33 -> 0
A36: INTEREST PAYABLE | B36: =ROUND((B35*J35/365)*18/100,0) -> 0 | C36: =ROUND((C35*$J$35/365)*18/100,0) -> 0 | D36: =ROUND((D35*$J$35/365)*18/100,0) -> 0 | E36: =ROUND((E35*$J$35/365)*18/100,0) -> 0 | F36: =SUM(B36:E36) -> 0 | I36: LATE FESS | J36: =J35*50 -> 0
A37: TOTAL CHALLAN PAYABLE | B37: =+B35+B36 -> 0 | C37: =+C35+C36 -> 125054 | D37: =+D35+D36 -> 125150 | E37: =+E35+E36 -> 0 | F37: =SUMIF(B37:E37,">0") -> 250204 | I37: TOTAL | J37: =F37+J36 -> 250204

Sheet JUNe Working
D1: GST CALCULATION
A3: SR.NO. | B3: FLAT NO. | C3: AGREEMENT DONE | D3: AGREEMENT AMOUNT | E3: 1% GST | F3: 5% GST | G3: ADVANCES AMOUNT | H3: REVERSE GST ON ADVANCE | I3: AMOUNT PAID
A4: 1 | B4: 106 | C4: KAMLESH DANGI | D4: 7500000 | F4: =D4*5% -> 375000 | G4: 3500000 | H4: =G4*5% -> 175000 | I4: =F4-H4 -> 200000
A5: 2 | B5: 504 | C5: KHATUSHYAM CONSTRUCTION | D5: 4400000 | E5: =+D5*1% -> 44000 | H5: =G5*5% -> 0 | I5: =E5-H5 -> 44000
A6: 3 | F6: =D6*1% -> 0 | H6: =G6*5% -> 0 | I6: =F6-H6 -> 0
E7: 0 | F7: 0 | H7: 0 | I7: =SUM(I4:I6) -> 244000
D10: CALCULATION ON ADVANCES
B12: FLAT NO. | C12: NAME | D12: ADVANCE AMOUNT | E12: 1% GST | F12: 5% GST
B13: 1105 | C13: GLASTON DSOUZA | D13: 150000 | F13: =D13*5% -> 7500
F14: =D14*5% -> 0
F15: =D15*5% -> 0
F16: =D16*5% -> 0
E17: =SUM(E13:E16) -> 0 | F17: =SUM(F13:F16) -> 7500 | G17: 0 | H17: =I7+E17+F17 -> 251500
H18: =+H17/2 -> 125750
B20: Note: in june month Flat no 106, kamlesh dangi we have taken agreement amt 75,00,000 and GSt paid 3,75,000 (5%) but not deducted advance amt received in 22-23 Rs.35,00,000 so This amendment done in April 26 month

Sheet July-25
A1: SPACE HOME GST CALCULATION FOR THE MONTH OF JULY 2025
A2: OUTWARD SUPPLY | B2: 0.01 | E2: 0.05 | H2: 0.18 | K2: 0.28 | N2: CESS
B3: AMT | C3: CGST | D3: SGST | E3: AMT | F3: CGST | G3: SGST | H3: AMT | I3: CGST | J3: SGST | K3: AMT | L3: CGST | M3: SGST | N3: AMT | O3: 0.12
A4: SALES | B4: 50000 | C4: =B4*B2/2 -> 250 | D4: =B4*B2/2 -> 250 | E4: 5550000 | F4: =E4*E2/2 -> 138750 | G4: =E4*E2/2 -> 138750 | H4: 0 | I4: =H4*H2/2 -> 0 | J4: =H4*H2/2 -> 0 | K4: 0 | L4: =K4*K2/2 -> 0 | M4: =K4*K2/2 -> 0 | O4: =N4*O3 -> 0
A5: ADVANCE | B5: 0 | C5: 0 | D5: 0 | E5: 0 | F5: =E5*E2/2 -> 0 | G5: =E5*E2/2 -> 0 | L5: =K5*K2/2 -> 0 | M5: =K5*K2/2 -> 0 | O5: =N5*O3 -> 0
A7: INWARD SUPPLY | B7: 0.05 | E7: 0.12 | H7: 0.18 | K7: 0.28 | N7: CESS
B8: AMT | C8: CGST | D8: SGST | E8: AMT | F8: CGST | G8: SGST | H8: AMT | I8: CGST | J8: SGST | K8: AMT | L8: CGST | M8: SGST | N8: AMT | O8: 0.12
A9: PURCHASES | C9: =B9*B7/2 -> 0 | D9: =B9*B7/2 -> 0 | E9: 0 | F9: =E9*E7/2 -> 0 | G9: =E9*E7/2 -> 0 | I9: =H9*H7/2 -> 0 | J9: =I9 -> 0 | L9: =K9*K7/2 -> 0 | M9: =K9*K7/2 -> 0 | O9: =N9*O8 -> 0
A10: REVERSE | C10: =B10*B7/2 -> 0 | D10: =B10*B7/2 -> 0 | G10: =F10 -> 0 | I10: =H10*H7/2 -> 0 | J10: =+I10 -> 0 | L10: =K10*K7/2 -> 0 | M10: =K10*K7/2 -> 0 | O10: =N10*O8 -> 0
A11: RCM | C11: =B11*B7/2 -> 0 | D11: =B11*B7/2 -> 0 | F11: =E11*E7/2 -> 0 | G11: =E11*E7/2 -> 0 | I11: =H11*H7/2 -> 0 | J11: =H11*H7/2 -> 0 | L11: =K11*K7/2 -> 0 | M11: =L11 -> 0
A13: IGST OUTWARD SUPPLY | B13: 0.05 | D13: 0.12 | F13: 0.18 | H13: 0.28 | J13: EXEMPT SALES | L13: NON GST SALES
B14: AMT | C14: IGST | D14: AMT | E14: IGST | F14: AMT | G14: IGST | H14: AMT | I14: IGST | J14: AMOUNT | L14: AMOUNT
A15: SALES | C15: =B15*B13 -> 0 | D15: 0 | E15: =D15*D13 -> 0 | I15: =H15*H13 -> 0
A17: IGST INWARD SUPPLY | B17: 0.05 | D17: 0.12 | F17: 0.18 | H17: 0.28 | J17: EXEMPT PURCHASE | L17: NON GST PURCHASES/URD
B18: AMT | C18: IGST | D18: AMT | E18: IGST | F18: AMT | G18: IGST | H18: AMT | I18: IGST | J18: AMOUNT | L18: AMOUNT
A19: PURCHASE- AUG.22 | B19: 0 | C19: =B19*B17 -> 0 | D19: 0 | E19: =D19*D17 -> 0 | G19: =F19*F17 -> 0 | I19: =H19*H17 -> 0
A20: PURCHASES AUG.22 | C20: =B20*B17 -> 0 | E20: =D20*D17 -> 0 | F20: 0 | G20: =F20*F17 -> 0 | H20: 0 | I20: =H20*H17 -> 0
A22: PARTICULARS | B22: IGST | C22: CGST | D22: SGST | E22: CESS | G22: PARTICULARS | H22: IGST | I22: CGST | J22: SGST | K22: CESS | L22: L Y YR GP
A23: GST COLLECTED | B23: =+C15+E15+G15+I15 -> 0 | C23: =+C4+F4+I4+L4+C5+F5+I5+L5 -> 139000 | D23: =+D4+G4+J4+M4+D5+G5+J5+M5 -> 139000 | E23: =+O4 -> 0 | G23: RCM PAYABLE | H23: 0 | I23: =+C11+F11+I11+L11 -> 0 | J23: =+D11+G11+J11+M11 -> 0 | K23: =+O11 -> 0
A24: RCM PAYABLE | C24: =+C11+F11+I11+L11 -> 0 | D24: =+D11+G11+J11+M11 -> 0
A25: ITC CREDIT ON PURCHASES | B25: =C19+E19+G19+I19 -> 0 | C25: =+C9+F9+I9+L9 -> 0 | D25: =+D9+G9+J9+M9 -> 0 | E25: =+O9 -> 0 | G25: TAX FREE | H25: 0.05 | I25: 0.12 | J25: 0.18 | K25: 0.28 | L25: OVERALL
A26: ITC CREDIT ON EXPENSES | B26: =C20+E20+G20+I20 -> 0 | C26: =+C10+F10+I10+L10 -> 0 | D26: =+D10+G10+J10+M10 -> 0 | E26: =+O10 -> 0 | G26: =+-((J19+L19)/(J15+L15)*100)+100 -> #DIV/0! | H26: =-(+B9/B4*100)+100 -> 100 | I26: =-(+E9/E4*100)+100 -> 100 | J26: =-(+H9/H4*100)+100 -> #DIV/0! | K26: =-(+K9/K4*100)+100 -> #DIV/0! | L26: =-(((B9+E9+H9+K9+N9+B19+D19+F19+H19+J19+L19)/(B4+E4+H4+K4+N4+B15+D15+F15+H15+J15+L15))*100)+100 -> 100
A27: ITC CREDIT ON RCM | B27: =C21+E21+G21+I21 -> 0 | C27: =+C11+F11+I11+L11 -> 0 | D27: =+D11+G11+J11+M11 -> 0 | E27: =+O11 -> 0 | H27: TAXABLE | I27: TOTAL
A28: PREV CR LEDGER BAL | G28: TOTAL SALES | H28: =+B4+B5+E4+E5+H4+H5+K4+K5+B15+D15+F15+H15 -> 5600000 | I28: =+H28+J15+L15 -> 5600000
A29: PREVIOUS CASH BAL | B29: 0 | G29: TOTAL PURCHASE | H29: =+B9+E9+H9+K9+B19+D19+F19+H19 -> 0
A30: NET PAYABLE/REFUND | B30: =+B23+B24-B25-B26-B27-B28-B29 -> 0 | C30: =+C23+C24-C25-C26-C27-C28-C29 -> 139000 | D30: =+D23+D24-D25-D26-D27-D28-D29 -> 139000 | E30: =+E23+E24-E25-E26-E27-E28-E29 -> 0 | F30: =B30+C30+D30 -> 278000
A32: PARTICULARS | B32: IGST | C32: CGST | D32: SGST | E32: CESS | F32: TOTAL | I32: PARTICULARS | J32: GST
A33: FINAL AMOUNT PAYABLE | B33: =IF(B30<=0,0,IF(AND(C30+C29>0,D30+D29>0),B30,IF(C30+C29>0,MAX(0,B30+D30+D29),IF(D30+D29>0,MAX(0,B30+C30+C29),IF(AND(C29<>0,C30<0,D30<0),MAX(0,B30+C30+C29+D30+D29),IF(AND(C29<>0,C30<0),MAX(0,B30+C30+C29),IF(D29<>0,MAX(0,B30+C30+C29+D30+D29),IF(AND(C30<0,D30<0),MAX(0,B30+C30+D30),IF(AND(C30<0,D30>=0),MAX(0,B30+C30),IF(AND(C30>=0,D30<0),MAX(0,B30+D30),B30)))))))))) -> 0 | C33: =IF(C30<=0,0,IF(B30+B29>=0,C30,IF(AND(C30>0,B30<0),MAX(0,C30+B30+B29),C30))) -> 139000 | D33: =IF(D30<=0,0,IF(B30+B29>=0,D30,IF(AND(D30>0,B30+C30+B29<0,C30>0),MAX(0,D30+C30+B30+B29),IF(AND(D30>0,B30<0,C30<=0),MAX(0,D30+B30+B29),D30)))) -> 139000 | E33: =IF(E30<=0,0,E30) -> 0 | F33: =SUM(B33:E33) -> 278000 | I33: Due Date | J33: 45402
A34: RCM FINAL PAYABLE | B34: =+H23 -> 0 | C34: =IF(C33>=I23,0,I23-C33) -> 0 | D34: =IF(D33>=J23,0,J23-D33) -> 0 | E34: =IF(E33>=K23,0,K23-E33) -> 0 | F34: =SUM(B34:E34) -> 0 | I34: Payment | J34: 45402
A35: TOTAL PAYABLE | B35: =SUM(B33:B34) -> 0 | C35: =SUM(C33:C34) -> 139000 | D35: =SUM(D33:D34) -> 139000 | E35: =SUM(E33:E34) -> 0 | F35: =SUM(B35:E35) -> 278000 | I35: Delayed Days | J35: =J34-J33 -> 0
A36: INTEREST PAYABLE | B36: =ROUND((B35*J35/365)*18/100,0) -> 0 | C36: =ROUND((C35*$J$35/365)*18/100,0) -> 0 | D36: =ROUND((D35*$J$35/365)*18/100,0) -> 0 | E36: =ROUND((E35*$J$35/365)*18/100,0) -> 0 | F36: =SUM(B36:E36) -> 0 | I36: LATE FESS | J36: =J35*50 -> 0
A37: TOTAL CHALLAN PAYABLE | B37: =+B35+B36 -> 0 | C37: =+C35+C36 -> 139000 | D37: =+D35+D36 -> 139000 | E37: =+E35+E36 -> 0 | F37: =SUMIF(B37:E37,">0") -> 278000 | I37: TOTAL | J37: =F37+J36 -> 278000

Sheet July Working
D1: GST CALCULATION
A3: SR.NO. | B3: FLAT NO. | C3: AGREEMENT DONE | D3: AGREEMENT AMOUNT | E3: 1% GST | F3: 5% GST | G3: ADVANCES AMOUNT | H3: REVERSE GST ON ADVANCE | I3: AMOUNT PAID
A4: 1 | B4: 1105 | C4: GLASTON DSOUZA | D4: 5650000 | F4: =D4*5% -> 282500 | G4: 150000 | H4: =G4*5% -> 7500 | I4: =F4-H4 -> 275000
E5: 0 | F5: 0 | H5: 0 | I5: =SUM(I4:I4) -> 275000
D7: CALCULATION ON ADVANCES
B8: FLAT NO. | C8: NAME | D8: ADVANCE AMOUNT | E8: 1% GST | F8: 5% GST
B9: 1605 | C9: SHRUTIKA PATIL | D9: 50000 | E9: =D9*1% -> 500 | F9: 0
B10: 1509 | C10: RAJEEV DESAI | D10: 50000 | F10: =D10*5% -> 2500
F11: =D11*5% -> 0
F12: =D12*5% -> 0
E13: =SUM(E9:E12) -> 500 | F13: =SUM(F9:F12) -> 2500 | G13: 0 | H13: =I5+E13+F13 -> 278000
B15: Note: in june month Flat no 106, kamlesh dangi we have taken agreement amt 75,00,000 and GSt paid 3,75,000 (5%) but not deducted advance amt received in 22-23 Rs.35,00,000 so This amendment done in April 26 month

Sheet AUG 25
A1: SPACE HOME GST CALCULATION FOR THE MONTH OF AUGUST 2025
A2: OUTWARD SUPPLY | B2: 0.01 | E2: 0.05 | H2: 0.18 | K2: 0.28 | N2: CESS
B3: AMT | C3: CGST | D3: SGST | E3: AMT | F3: CGST | G3: SGST | H3: AMT | I3: CGST | J3: SGST | K3: AMT | L3: CGST | M3: SGST | N3: AMT | O3: 0.12
A4: SALES | C4: =B4*B2/2 -> 0 | D4: =B4*B2/2 -> 0 | E4: =+'Aug Working'!D13 -> 100001 | F4: =E4*E2/2 -> 2500.025 | G4: =E4*E2/2 -> 2500.025 | H4: 0 | I4: =H4*H2/2 -> 0 | J4: =H4*H2/2 -> 0 | K4: 0 | L4: =K4*K2/2 -> 0 | M4: =K4*K2/2 -> 0 | O4: =N4*O3 -> 0
A5: ADVANCE | B5: 0 | C5: 0 | D5: 0 | E5: 0 | F5: =E5*E2/2 -> 0 | G5: =E5*E2/2 -> 0 | L5: =K5*K2/2 -> 0 | M5: =K5*K2/2 -> 0 | O5: =N5*O3 -> 0
A7: INWARD SUPPLY | B7: 0.05 | E7: 0.12 | H7: 0.18 | K7: 0.28 | N7: CESS
B8: AMT | C8: CGST | D8: SGST | E8: AMT | F8: CGST | G8: SGST | H8: AMT | I8: CGST | J8: SGST | K8: AMT | L8: CGST | M8: SGST | N8: AMT | O8: 0.12
A9: PURCHASES | C9: =B9*B7/2 -> 0 | D9: =B9*B7/2 -> 0 | E9: 0 | F9: =E9*E7/2 -> 0 | G9: =E9*E7/2 -> 0 | I9: =H9*H7/2 -> 0 | J9: =I9 -> 0 | L9: =K9*K7/2 -> 0 | M9: =K9*K7/2 -> 0 | O9: =N9*O8 -> 0
A10: REVERSE | C10: =B10*B7/2 -> 0 | D10: =B10*B7/2 -> 0 | G10: =F10 -> 0 | I10: =H10*H7/2 -> 0 | J10: =+I10 -> 0 | L10: =K10*K7/2 -> 0 | M10: =K10*K7/2 -> 0 | O10: =N10*O8 -> 0
A11: RCM | C11: =B11*B7/2 -> 0 | D11: =B11*B7/2 -> 0 | F11: =E11*E7/2 -> 0 | G11: =E11*E7/2 -> 0 | I11: =H11*H7/2 -> 0 | J11: =H11*H7/2 -> 0 | L11: =K11*K7/2 -> 0 | M11: =L11 -> 0
A13: IGST OUTWARD SUPPLY | B13: 0.05 | D13: 0.12 | F13: 0.18 | H13: 0.28 | J13: EXEMPT SALES | L13: NON GST SALES
B14: AMT | C14: IGST | D14: AMT | E14: IGST | F14: AMT | G14: IGST | H14: AMT | I14: IGST | J14: AMOUNT | L14: AMOUNT
A15: SALES | C15: =B15*B13 -> 0 | D15: 0 | E15: =D15*D13 -> 0 | I15: =H15*H13 -> 0
A17: IGST INWARD SUPPLY | B17: 0.05 | D17: 0.12 | F17: 0.18 | H17: 0.28 | J17: EXEMPT PURCHASE | L17: NON GST PURCHASES/URD
B18: AMT | C18: IGST | D18: AMT | E18: IGST | F18: AMT | G18: IGST | H18: AMT | I18: IGST | J18: AMOUNT | L18: AMOUNT
A19: PURCHASE- AUG.22 | B19: 0 | C19: =B19*B17 -> 0 | D19: 0 | E19: =D19*D17 -> 0 | G19: =F19*F17 -> 0 | I19: =H19*H17 -> 0
A20: PURCHASES AUG.22 | C20: =B20*B17 -> 0 | E20: =D20*D17 -> 0 | F20: 0 | G20: =F20*F17 -> 0 | H20: 0 | I20: =H20*H17 -> 0
A22: PARTICULARS | B22: IGST | C22: CGST | D22: SGST | E22: CESS | G22: PARTICULARS | H22: IGST | I22: CGST | J22: SGST | K22: CESS | L22: L Y YR GP
A23: GST COLLECTED | B23: =+C15+E15+G15+I15 -> 0 | C23: =+C4+F4+I4+L4+C5+F5+I5+L5 -> 2500.025 | D23: =+D4+G4+J4+M4+D5+G5+J5+M5 -> 2500.025 | E23: =+O4 -> 0 | G23: RCM PAYABLE | H23: 0 | I23: =+C11+F11+I11+L11 -> 0 | J23: =+D11+G11+J11+M11 -> 0 | K23: =+O11 -> 0
A24: RCM PAYABLE | C24: =+C11+F11+I11+L11 -> 0 | D24: =+D11+G11+J11+M11 -> 0
A25: ITC CREDIT ON PURCHASES | B25: =C19+E19+G19+I19 -> 0 | C25: =+C9+F9+I9+L9 -> 0 | D25: =+D9+G9+J9+M9 -> 0 | E25: =+O9 -> 0 | G25: TAX FREE | H25: 0.05 | I25: 0.12 | J25: 0.18 | K25: 0.28 | L25: OVERALL
A26: ITC CREDIT ON EXPENSES | B26: =C20+E20+G20+I20 -> 0 | C26: =+C10+F10+I10+L10 -> 0 | D26: =+D10+G10+J10+M10 -> 0 | E26: =+O10 -> 0 | G26: =+-((J19+L19)/(J15+L15)*100)+100 -> #DIV/0! | H26: =-(+B9/B4*100)+100 -> #DIV/0! | I26: =-(+E9/E4*100)+100 -> 100 | J26: =-(+H9/H4*100)+100 -> #DIV/0! | K26: =-(+K9/K4*100)+100 -> #DIV/0! | L26: =-(((B9+E9+H9+K9+N9+B19+D19+F19+H19+J19+L19)/(B4+E4+H4+K4+N4+B15+D15+F15+H15+J15+L15))*100)+100 -> 100
A27: ITC CREDIT ON RCM | B27: =C21+E21+G21+I21 -> 0 | C27: =+C11+F11+I11+L11 -> 0 | D27: =+D11+G11+J11+M11 -> 0 | E27: =+O11 -> 0 | H27: TAXABLE | I27: TOTAL
A28: PREV CR LEDGER BAL | G28: TOTAL SALES | H28: =+B4+B5+E4+E5+H4+H5+K4+K5+B15+D15+F15+H15 -> 100001 | I28: =+H28+J15+L15 -> 100001
A29: PREVIOUS CASH BAL | B29: 0 | G29: TOTAL PURCHASE | H29: =+B9+E9+H9+K9+B19+D19+F19+H19 -> 0
A30: NET PAYABLE/REFUND | B30: =+B23+B24-B25-B26-B27-B28-B29 -> 0 | C30: =+C23+C24-C25-C26-C27-C28-C29 -> 2500.025 | D30: =+D23+D24-D25-D26-D27-D28-D29 -> 2500.025 | E30: =+E23+E24-E25-E26-E27-E28-E29 -> 0 | F30: =B30+C30+D30 -> 5000.05
A32: PARTICULARS | B32: IGST | C32: CGST | D32: SGST | E32: CESS | F32: TOTAL | I32: PARTICULARS | J32: GST
A33: FINAL AMOUNT PAYABLE | B33: =IF(B30<=0,0,IF(AND(C30+C29>0,D30+D29>0),B30,IF(C30+C29>0,MAX(0,B30+D30+D29),IF(D30+D29>0,MAX(0,B30+C30+C29),IF(AND(C29<>0,C30<0,D30<0),MAX(0,B30+C30+C29+D30+D29),IF(AND(C29<>0,C30<0),MAX(0,B30+C30+C29),IF(D29<>0,MAX(0,B30+C30+C29+D30+D29),IF(AND(C30<0,D30<0),MAX(0,B30+C30+D30),IF(AND(C30<0,D30>=0),MAX(0,B30+C30),IF(AND(C30>=0,D30<0),MAX(0,B30+D30),B30)))))))))) -> 0 | C33: =IF(C30<=0,0,IF(B30+B29>=0,C30,IF(AND(C30>0,B30<0),MAX(0,C30+B30+B29),C30))) -> 2500.025 | D33: =IF(D30<=0,0,IF(B30+B29>=0,D30,IF(AND(D30>0,B30+C30+B29<0,C30>0),MAX(0,D30+C30+B30+B29),IF(AND(D30>0,B30<0,C30<=0),MAX(0,D30+B30+B29),D30)))) -> 2500.025 | E33: =IF(E30<=0,0,E30) -> 0 | F33: =SUM(B33:E33) -> 5000.05 | I33: Due Date | J33: 45524
A34: RCM FINAL PAYABLE | B34: =+H23 -> 0 | C34: =IF(C33>=I23,0,I23-C33) -> 0 | D34: =IF(D33>=J23,0,J23-D33) -> 0 | E34: =IF(E33>=K23,0,K23-E33) -> 0 | F34: =SUM(B34:E34) -> 0 | I34: Payment | J34: 45524
A35: TOTAL PAYABLE | B35: =SUM(B33:B34) -> 0 | C35: =SUM(C33:C34) -> 2500.025 | D35: =SUM(D33:D34) -> 2500.025 | E35: =SUM(E33:E34) -> 0 | F35: =SUM(B35:E35) -> 5000.05 | I35: Delayed Days | J35: =J34-J33 -> 0
A36: INTEREST PAYABLE | B36: =ROUND((B35*J35/365)*18/100,0) -> 0 | C36: =ROUND((C35*$J$35/365)*18/100,0) -> 0 | D36: =ROUND((D35*$J$35/365)*18/100,0) -> 0 | E36: =ROUND((E35*$J$35/365)*18/100,0) -> 0 | F36: =SUM(B36:E36) -> 0 | I36: LATE FESS | J36: =J35*50 -> 0
A37: TOTAL CHALLAN PAYABLE | B37: =+B35+B36 -> 0 | C37: =+C35+C36 -> 2500.025 | D37: =+D35+D36 -> 2500.025 | E37: =+E35+E36 -> 0 | F37: =SUMIF(B37:E37,">0") -> 5000.05 | I37: TOTAL | J37: =F37+J36 -> 5000.05

Sheet Aug Working
D1: GST CALCULATION
A3: SR.NO. | B3: FLAT NO. | C3: AGREEMENT DONE | D3: AGREEMENT AMOUNT | E3: 1% GST | F3: 5% GST | G3: ADVANCES AMOUNT | H3: REVERSE GST ON ADVANCE | I3: AMOUNT PAID
A4: 1 | F4: =D4*5% -> 0 | G4: 0 | H4: =G4*5% -> 0 | I4: =F4-H4 -> 0
A5: 2 | E5: 0 | F5: =D5*5% -> 0 | H5: =G5*5% -> 0 | I5: =F5-H5 -> 0
A6: 3 | F6: =D6*1% -> 0 | H6: =G6*5% -> 0 | I6: =F6-H6 -> 0
E7: 0 | F7: 0 | H7: 0 | I7: =SUM(I4:I6) -> 0
D10: CALCULATION ON ADVANCES
B12: FLAT NO. | C12: NAME | D12: ADVANCE AMOUNT | E12: 1% GST | F12: 5% GST
B13: 708 | C13: ANJALI VISHWAKARMA | D13: 100001 | E13: 0 | F13: =D13*5% -> 5000.05
F14: =D14*5% -> 0
F15: =D15*5% -> 0
F16: =D16*5% -> 0
E17: =SUM(E13:E16) -> 0 | F17: =SUM(F13:F16) -> 5000.05 | G17: 0 | H17: =I7+E17+F17 -> 5000.05

Sheet Sept 25
A1: SPACE HOME GST CALCULATION FOR THE MONTH OF SEPTEMBER 2025
A2: OUTWARD SUPPLY | B2: 0.01 | E2: 0.05 | H2: 0.18 | K2: 0.28 | N2: CESS
B3: AMT | C3: CGST | D3: SGST | E3: AMT | F3: CGST | G3: SGST | H3: AMT | I3: CGST | J3: SGST | K3: AMT | L3: CGST | M3: SGST | N3: AMT | O3: 0.12
A4: SALES | C4: =B4*B2/2 -> 0 | D4: =B4*B2/2 -> 0 | E4: =+'Sept Working'!D4-'Sept Working'!G4+'Sept Working'!D13+'Sept Working'!D14 -> 8985739 | F4: =E4*E2/2 -> 224643.48 | G4: =E4*E2/2 -> 224643.48 | H4: 0 | I4: =H4*H2/2 -> 0 | J4: =H4*H2/2 -> 0 | K4: 0 | L4: =K4*K2/2 -> 0 | M4: =K4*K2/2 -> 0 | O4: =N4*O3 -> 0
A5: ADVANCE | B5: 0 | C5: 0 | D5: 0 | E5: 0 | F5: =E5*E2/2 -> 0 | G5: =E5*E2/2 -> 0 | L5: =K5*K2/2 -> 0 | M5: =K5*K2/2 -> 0 | O5: =N5*O3 -> 0
A7: INWARD SUPPLY | B7: 0.05 | E7: 0.12 | H7: 0.18 | K7: 0.28 | N7: CESS
B8: AMT | C8: CGST | D8: SGST | E8: AMT | F8: CGST | G8: SGST | H8: AMT | I8: CGST | J8: SGST | K8: AMT | L8: CGST | M8: SGST | N8: AMT | O8: 0.12
A9: PURCHASES | C9: =B9*B7/2 -> 0 | D9: =B9*B7/2 -> 0 | E9: 0 | F9: =E9*E7/2 -> 0 | G9: =E9*E7/2 -> 0 | I9: =H9*H7/2 -> 0 | J9: =I9 -> 0 | L9: =K9*K7/2 -> 0 | M9: =K9*K7/2 -> 0 | O9: =N9*O8 -> 0
A10: REVERSE | C10: =B10*B7/2 -> 0 | D10: =B10*B7/2 -> 0 | G10: =F10 -> 0 | I10: =H10*H7/2 -> 0 | J10: =+I10 -> 0 | L10: =K10*K7/2 -> 0 | M10: =K10*K7/2 -> 0 | O10: =N10*O8 -> 0
A11: RCM | C11: =B11*B7/2 -> 0 | D11: =B11*B7/2 -> 0 | F11: =E11*E7/2 -> 0 | G11: =E11*E7/2 -> 0 | I11: =H11*H7/2 -> 0 | J11: =H11*H7/2 -> 0 | L11: =K11*K7/2 -> 0 | M11: =L11 -> 0
A13: IGST OUTWARD SUPPLY | B13: 0.05 | D13: 0.12 | F13: 0.18 | H13: 0.28 | J13: EXEMPT SALES | L13: NON GST SALES
B14: AMT | C14: IGST | D14: AMT | E14: IGST | F14: AMT | G14: IGST | H14: AMT | I14: IGST | J14: AMOUNT | L14: AMOUNT
A15: SALES | C15: =B15*B13 -> 0 | D15: 0 | E15: =D15*D13 -> 0 | I15: =H15*H13 -> 0
A17: IGST INWARD SUPPLY | B17: 0.05 | D17: 0.12 | F17: 0.18 | H17: 0.28 | J17: EXEMPT PURCHASE | L17: NON GST PURCHASES/URD
B18: AMT | C18: IGST | D18: AMT | E18: IGST | F18: AMT | G18: IGST | H18: AMT | I18: IGST | J18: AMOUNT | L18: AMOUNT
A19: PURCHASE- AUG.22 | B19: 0 | C19: =B19*B17 -> 0 | D19: 0 | E19: =D19*D17 -> 0 | G19: =F19*F17 -> 0 | I19: =H19*H17 -> 0
A20: PURCHASES AUG.22 | C20: =B20*B17 -> 0 | E20: =D20*D17 -> 0 | F20: 0 | G20: =F20*F17 -> 0 | H20: 0 | I20: =H20*H17 -> 0
A22: PARTICULARS | B22: IGST | C22: CGST | D22: SGST | E22: CESS | G22: PARTICULARS | H22: IGST | I22: CGST | J22: SGST | K22: CESS | L22: L Y YR GP
A23: GST COLLECTED | B23: =+C15+E15+G15+I15 -> 0 | C23: =+C4+F4+I4+L4+C5+F5+I5+L5 -> 224643.48 | D23: =+D4+G4+J4+M4+D5+G5+J5+M5 -> 224643.48 | E23: =+O4 -> 0 | G23: RCM PAYABLE | H23: 0 | I23: =+C11+F11+I11+L11 -> 0 | J23: =+D11+G11+J11+M11 -> 0 | K23: =+O11 -> 0
A24: RCM PAYABLE | C24: =+C11+F11+I11+L11 -> 0 | D24: =+D11+G11+J11+M11 -> 0
A25: ITC CREDIT ON PURCHASES | B25: =C19+E19+G19+I19 -> 0 | C25: =+C9+F9+I9+L9 -> 0 | D25: =+D9+G9+J9+M9 -> 0 | E25: =+O9 -> 0 | G25: TAX FREE | H25: 0.05 | I25: 0.12 | J25: 0.18 | K25: 0.28 | L25: OVERALL
A26: ITC CREDIT ON EXPENSES | B26: =C20+E20+G20+I20 -> 0 | C26: =+C10+F10+I10+L10 -> 0 | D26: =+D10+G10+J10+M10 -> 0 | E26: =+O10 -> 0 | G26: =+-((J19+L19)/(J15+L15)*100)+100 -> #DIV/0! | H26: =-(+B9/B4*100)+100 -> #DIV/0! | I26: =-(+E9/E4*100)+100 -> 100 | J26: =-(+H9/H4*100)+100 -> #DIV/0! | K26: =-(+K9/K4*100)+100 -> #DIV/0! | L26: =-(((B9+E9+H9+K9+N9+B19+D19+F19+H19+J19+L19)/(B4+E4+H4+K4+N4+B15+D15+F15+H15+J15+L15))*100)+100 -> 100
A27: ITC CREDIT ON RCM | B27: =C21+E21+G21+I21 -> 0 | C27: =+C11+F11+I11+L11 -> 0 | D27: =+D11+G11+J11+M11 -> 0 | E27: =+O11 -> 0 | H27: TAXABLE | I27: TOTAL
A28: PREV CR LEDGER BAL | G28: TOTAL SALES | H28: =+B4+B5+E4+E5+H4+H5+K4+K5+B15+D15+F15+H15 -> 8985739 | I28: =+H28+J15+L15 -> 8985739
A29: PREVIOUS CASH BAL | B29: 0 | G29: TOTAL PURCHASE | H29: =+B9+E9+H9+K9+B19+D19+F19+H19 -> 0
A30: NET PAYABLE/REFUND | B30: =+B23+B24-B25-B26-B27-B28-B29 -> 0 | C30: =+C23+C24-C25-C26-C27-C28-C29 -> 224643.48 | D30: =+D23+D24-D25-D26-D27-D28-D29 -> 224643.48 | E30: =+E23+E24-E25-E26-E27-E28-E29 -> 0 | F30: =B30+C30+D30 -> 449286.95
A32: PARTICULARS | B32: IGST | C32: CGST | D32: SGST | E32: CESS | F32: TOTAL | I32: PARTICULARS | J32: GST
A33: FINAL AMOUNT PAYABLE | B33: =IF(B30<=0,0,IF(AND(C30+C29>0,D30+D29>0),B30,IF(C30+C29>0,MAX(0,B30+D30+D29),IF(D30+D29>0,MAX(0,B30+C30+C29),IF(AND(C29<>0,C30<0,D30<0),MAX(0,B30+C30+C29+D30+D29),IF(AND(C29<>0,C30<0),MAX(0,B30+C30+C29),IF(D29<>0,MAX(0,B30+C30+C29+D30+D29),IF(AND(C30<0,D30<0),MAX(0,B30+C30+D30),IF(AND(C30<0,D30>=0),MAX(0,B30+C30),IF(AND(C30>=0,D30<0),MAX(0,B30+D30),B30)))))))))) -> 0 | C33: =IF(C30<=0,0,IF(B30+B29>=0,C30,IF(AND(C30>0,B30<0),MAX(0,C30+B30+B29),C30))) -> 224643.48 | D33: =IF(D30<=0,0,IF(B30+B29>=0,D30,IF(AND(D30>0,B30+C30+B29<0,C30>0),MAX(0,D30+C30+B30+B29),IF(AND(D30>0,B30<0,C30<=0),MAX(0,D30+B30+B29),D30)))) -> 224643.48 | E33: =IF(E30<=0,0,E30) -> 0 | F33: =SUM(B33:E33) -> 449286.95 | I33: Due Date | J33: 45524
A34: RCM FINAL PAYABLE | B34: =+H23 -> 0 | C34: =IF(C33>=I23,0,I23-C33) -> 0 | D34: =IF(D33>=J23,0,J23-D33) -> 0 | E34: =IF(E33>=K23,0,K23-E33) -> 0 | F34: =SUM(B34:E34) -> 0 | I34: Payment | J34: 45524
A35: TOTAL PAYABLE | B35: =SUM(B33:B34) -> 0 | C35: =SUM(C33:C34) -> 224643.48 | D35: =SUM(D33:D34) -> 224643.48 | E35: =SUM(E33:E34) -> 0 | F35: =SUM(B35:E35) -> 449286.95 | I35: Delayed Days | J35: =J34-J33 -> 0
A36: INTEREST PAYABLE | B36: =ROUND((B35*J35/365)*18/100,0) -> 0 | C36: =ROUND((C35*$J$35/365)*18/100,0) -> 0 | D36: =ROUND((D35*$J$35/365)*18/100,0) -> 0 | E36: =ROUND((E35*$J$35/365)*18/100,0) -> 0 | F36: =SUM(B36:E36) -> 0 | I36: LATE FESS | J36: =J35*50 -> 0
A37: TOTAL CHALLAN PAYABLE | B37: =+B35+B36 -> 0 | C37: =+C35+C36 -> 224643.48 | D37: =+D35+D36 -> 224643.48 | E37: =+E35+E36 -> 0 | F37: =SUMIF(B37:E37,">0") -> 449286.95 | I37: TOTAL | J37: =F37+J36 -> 449286.95

Sheet Sept Working
D1: GST CALCULATION
A3: SR.NO. | B3: FLAT NO. | C3: AGREEMENT DONE | D3: AGREEMENT AMOUNT | E3: 1% GST | F3: 5% GST | G3: ADVANCES AMOUNT | H3: REVERSE GST ON ADVANCE | I3: AMOUNT PAID
A4: 1 | B4: 708 | C4: ANJALI VISHWAKARMA | D4: 8035740 | F4: =D4*5% -> 401787 | G4: 100001 | H4: =G4*5%-0.05 -> 5000 | I4: =F4-H4 -> 396787
A5: 2 | E5: 0 | F5: =D5*5% -> 0 | H5: =G5*5% -> 0 | I5: =F5-H5 -> 0
A6: 3 | F6: =D6*1% -> 0 | H6: =G6*5% -> 0 | I6: =F6-H6 -> 0
E7: 0 | F7: 0 | H7: 0 | I7: =SUM(I4:I6) -> 396787
D10: CALCULATION ON ADVANCES
B12: FLAT NO. | C12: NAME | D12: ADVANCE AMOUNT | E12: 1% GST | F12: 5% GST
B13: 1304 | C13: MICHAEL NUNES | D13: 50000 | E13: 0 | F13: =D13*5% -> 2500
B14: 1509 | C14: RAJEEV DESAI | D14: 1000000 | F14: =D14*5% -> 50000
F15: =D15*5% -> 0
F16: =D16*5% -> 0
E17: =SUM(E13:E16) -> 0 | F17: =SUM(F13:F16) -> 52500 | G17: 0 | H17: =I7+E17+F17 -> 449287

Sheet Oct 25
A1: SPACE HOME GST CALCULATION FOR THE MONTH OF OCTOBER 2025
A2: OUTWARD SUPPLY | B2: 0.01 | E2: 0.05 | H2: 0.18 | K2: 0.28 | N2: CESS
B3: AMT | C3: CGST | D3: SGST | E3: AMT | F3: CGST | G3: SGST | H3: AMT | I3: CGST | J3: SGST | K3: AMT | L3: CGST | M3: SGST | N3: AMT | O3: 0.12
A4: SALES | B4: =+'Oct Working'!D16 -> 174500 | C4: =B4*B2/2 -> 872.5 | D4: =B4*B2/2 -> 872.5 | E4: =+'Oct Working'!D4-'Oct Working'!G4+'Oct Working'!D14+'Oct Working'!D15 -> 9902600 | F4: =E4*E2/2 -> 247565 | G4: =E4*E2/2 -> 247565 | H4: 0 | I4: =H4*H2/2 -> 0 | J4: =H4*H2/2 -> 0 | K4: 0 | L4: =K4*K2/2 -> 0 | M4: =K4*K2/2 -> 0 | O4: =N4*O3 -> 0
A5: ADVANCE | B5: 0 | C5: 0 | D5: 0 | E5: 0 | F5: =E5*E2/2 -> 0 | G5: =E5*E2/2 -> 0 | L5: =K5*K2/2 -> 0 | M5: =K5*K2/2 -> 0 | O5: =N5*O3 -> 0
A7: INWARD SUPPLY | B7: 0.05 | E7: 0.12 | H7: 0.18 | K7: 0.28 | N7: CESS
B8: AMT | C8: CGST | D8: SGST | E8: AMT | F8: CGST | G8: SGST | H8: AMT | I8: CGST | J8: SGST | K8: AMT | L8: CGST | M8: SGST | N8: AMT | O8: 0.12
A9: PURCHASES | C9: =B9*B7/2 -> 0 | D9: =B9*B7/2 -> 0 | E9: 0 | F9: =E9*E7/2 -> 0 | G9: =E9*E7/2 -> 0 | I9: =H9*H7/2 -> 0 | J9: =I9 -> 0 | L9: =K9*K7/2 -> 0 | M9: =K9*K7/2 -> 0 | O9: =N9*O8 -> 0
A10: REVERSE | C10: =B10*B7/2 -> 0 | D10: =B10*B7/2 -> 0 | G10: =F10 -> 0 | I10: =H10*H7/2 -> 0 | J10: =+I10 -> 0 | L10: =K10*K7/2 -> 0 | M10: =K10*K7/2 -> 0 | O10: =N10*O8 -> 0
A11: RCM | C11: =B11*B7/2 -> 0 | D11: =B11*B7/2 -> 0 | F11: =E11*E7/2 -> 0 | G11: =E11*E7/2 -> 0 | I11: =H11*H7/2 -> 0 | J11: =H11*H7/2 -> 0 | L11: =K11*K7/2 -> 0 | M11: =L11 -> 0
A13: IGST OUTWARD SUPPLY | B13: 0.05 | D13: 0.12 | F13: 0.18 | H13: 0.28 | J13: EXEMPT SALES | L13: NON GST SALES
B14: AMT | C14: IGST | D14: AMT | E14: IGST | F14: AMT | G14: IGST | H14: AMT | I14: IGST | J14: AMOUNT | L14: AMOUNT
A15: SALES | C15: =B15*B13 -> 0 | D15: 0 | E15: =D15*D13 -> 0 | I15: =H15*H13 -> 0
A17: IGST INWARD SUPPLY | B17: 0.05 | D17: 0.12 | F17: 0.18 | H17: 0.28 | J17: EXEMPT PURCHASE | L17: NON GST PURCHASES/URD
B18: AMT | C18: IGST | D18: AMT | E18: IGST | F18: AMT | G18: IGST | H18: AMT | I18: IGST | J18: AMOUNT | L18: AMOUNT
A19: PURCHASE- AUG.22 | B19: 0 | C19: =B19*B17 -> 0 | D19: 0 | E19: =D19*D17 -> 0 | G19: =F19*F17 -> 0 | I19: =H19*H17 -> 0
A20: PURCHASES AUG.22 | C20: =B20*B17 -> 0 | E20: =D20*D17 -> 0 | F20: 0 | G20: =F20*F17 -> 0 | H20: 0 | I20: =H20*H17 -> 0
A22: PARTICULARS | B22: IGST | C22: CGST | D22: SGST | E22: CESS | G22: PARTICULARS | H22: IGST | I22: CGST | J22: SGST | K22: CESS | L22: L Y YR GP
A23: GST COLLECTED | B23: =+C15+E15+G15+I15 -> 0 | C23: =+C4+F4+I4+L4+C5+F5+I5+L5 -> 248437.5 | D23: =+D4+G4+J4+M4+D5+G5+J5+M5 -> 248437.5 | E23: =+O4 -> 0 | G23: RCM PAYABLE | H23: 0 | I23: =+C11+F11+I11+L11 -> 0 | J23: =+D11+G11+J11+M11 -> 0 | K23: =+O11 -> 0
A24: RCM PAYABLE | C24: =+C11+F11+I11+L11 -> 0 | D24: =+D11+G11+J11+M11 -> 0
A25: ITC CREDIT ON PURCHASES | B25: =C19+E19+G19+I19 -> 0 | C25: =+C9+F9+I9+L9 -> 0 | D25: =+D9+G9+J9+M9 -> 0 | E25: =+O9 -> 0 | G25: TAX FREE | H25: 0.05 | I25: 0.12 | J25: 0.18 | K25: 0.28 | L25: OVERALL
A26: ITC CREDIT ON EXPENSES | B26: =C20+E20+G20+I20 -> 0 | C26: =+C10+F10+I10+L10 -> 0 | D26: =+D10+G10+J10+M10 -> 0 | E26: =+O10 -> 0 | G26: =+-((J19+L19)/(J15+L15)*100)+100 -> #DIV/0! | H26: =-(+B9/B4*100)+100 -> 100 | I26: =-(+E9/E4*100)+100 -> 100 | J26: =-(+H9/H4*100)+100 -> #DIV/0! | K26: =-(+K9/K4*100)+100 -> #DIV/0! | L26: =-(((B9+E9+H9+K9+N9+B19+D19+F19+H19+J19+L19)/(B4+E4+H4+K4+N4+B15+D15+F15+H15+J15+L15))*100)+100 -> 100
A27: ITC CREDIT ON RCM | B27: =C21+E21+G21+I21 -> 0 | C27: =+C11+F11+I11+L11 -> 0 | D27: =+D11+G11+J11+M11 -> 0 | E27: =+O11 -> 0 | H27: TAXABLE | I27: TOTAL
A28: PREV CR LEDGER BAL | G28: TOTAL SALES | H28: =+B4+B5+E4+E5+H4+H5+K4+K5+B15+D15+F15+H15 -> 10077100 | I28: =+H28+J15+L15 -> 10077100
A29: PREVIOUS CASH BAL | B29: 0 | G29: TOTAL PURCHASE | H29: =+B9+E9+H9+K9+B19+D19+F19+H19 -> 0 | L29: 995411 HSN code
A30: NET PAYABLE/REFUND | B30: =+B23+B24-B25-B26-B27-B28-B29 -> 0 | C30: =+C23+C24-C25-C26-C27-C28-C29 -> 248437.5 | D30: =+D23+D24-D25-D26-D27-D28-D29 -> 248437.5 | E30: =+E23+E24-E25-E26-E27-E28-E29 -> 0 | F30: =B30+C30+D30 -> 496875
A32: PARTICULARS | B32: IGST | C32: CGST | D32: SGST | E32: CESS | F32: TOTAL | I32: PARTICULARS | J32: GST
A33: FINAL AMOUNT PAYABLE | B33: =IF(B30<=0,0,IF(AND(C30+C29>0,D30+D29>0),B30,IF(C30+C29>0,MAX(0,B30+D30+D29),IF(D30+D29>0,MAX(0,B30+C30+C29),IF(AND(C29<>0,C30<0,D30<0),MAX(0,B30+C30+C29+D30+D29),IF(AND(C29<>0,C30<0),MAX(0,B30+C30+C29),IF(D29<>0,MAX(0,B30+C30+C29+D30+D29),IF(AND(C30<0,D30<0),MAX(0,B30+C30+D30),IF(AND(C30<0,D30>=0),MAX(0,B30+C30),IF(AND(C30>=0,D30<0),MAX(0,B30+D30),B30)))))))))) -> 0 | C33: =IF(C30<=0,0,IF(B30+B29>=0,C30,IF(AND(C30>0,B30<0),MAX(0,C30+B30+B29),C30))) -> 248437.5 | D33: =IF(D30<=0,0,IF(B30+B29>=0,D30,IF(AND(D30>0,B30+C30+B29<0,C30>0),MAX(0,D30+C30+B30+B29),IF(AND(D30>0,B30<0,C30<=0),MAX(0,D30+B30+B29),D30)))) -> 248437.5 | E33: =IF(E30<=0,0,E30) -> 0 | F33: =SUM(B33:E33) -> 496875 | I33: Due Date | J33: 45524
A34: RCM FINAL PAYABLE | B34: =+H23 -> 0 | C34: =IF(C33>=I23,0,I23-C33) -> 0 | D34: =IF(D33>=J23,0,J23-D33) -> 0 | E34: =IF(E33>=K23,0,K23-E33) -> 0 | F34: =SUM(B34:E34) -> 0 | I34: Payment | J34: 45524
A35: TOTAL PAYABLE | B35: =SUM(B33:B34) -> 0 | C35: =SUM(C33:C34) -> 248437.5 | D35: =SUM(D33:D34) -> 248437.5 | E35: =SUM(E33:E34) -> 0 | F35: =SUM(B35:E35) -> 496875 | I35: Delayed Days | J35: =J34-J33 -> 0
A36: INTEREST PAYABLE | B36: =ROUND((B35*J35/365)*18/100,0) -> 0 | C36: =ROUND((C35*$J$35/365)*18/100,0) -> 0 | D36: =ROUND((D35*$J$35/365)*18/100,0) -> 0 | E36: =ROUND((E35*$J$35/365)*18/100,0) -> 0 | F36: =SUM(B36:E36) -> 0 | I36: LATE FESS | J36: =J35*50 -> 0
A37: TOTAL CHALLAN PAYABLE | B37: =+B35+B36 -> 0 | C37: =+C35+C36 -> 248437.5 | D37: =+D35+D36 -> 248437.5 | E37: =+E35+E36 -> 0 | F37: =SUMIF(B37:E37,">0") -> 496875 | I37: TOTAL | J37: =F37+J36 -> 496875

Sheet Oct Working
D1: GST CALCULATION
A3: SR.NO. | B3: FLAT NO. | C3: AGREEMENT DONE | D3: AGREEMENT AMOUNT | E3: 1% GST | F3: 5% GST | G3: ADVANCES AMOUNT | H3: REVERSE GST ON ADVANCE | I3: AMOUNT PAID
A4: 1 | B4: 1304 | C4: MICHAEL NUNES | D4: 6901500 | F4: =D4*5% -> 345075 | G4: 50000 | H4: =G4*5% -> 2500 | I4: =F4-H4 -> 342575
A5: 2 | E5: 0 | F5: =D5*5% -> 0 | H5: =G5*5% -> 0 | I5: =F5-H5 -> 0
A6: 3 | F6: =D6*1% -> 0 | H6: =G6*5% -> 0 | I6: =F6-H6 -> 0
E7: 0 | F7: 0 | H7: 0 | I7: =SUM(I4:I6) -> 342575
D10: CALCULATION ON ADVANCES
B12: FLAT NO. | C12: NAME | D12: ADVANCE AMOUNT | E12: 1% GST | F12: 5% GST
F13: 0
B14: 1606 | C14: RAJEEV DESAI | D14: 3000100 | F14: =D14*5% -> 150005
B15: 1805 | C15: SHAKTIGANESH DANDE | D15: 51000 | F15: =D15*5% -> 2550
B16: 1605 | C16: Shrutika Patil | D16: 174500 | E16: =+D16*1% -> 1745
E19: =SUM(E13:E16) -> 1745 | F19: =SUM(F13:F16) -> 152555 | G19: 0 | H19: =I7+E19+F19 -> 496875
C22: FLAT NO.1605 CANCELLED in Nov month

Sheet NOV 25
A1: SPACE HOME GST CALCULATION FOR THE MONTH OF NOVEMBER 2025
A2: OUTWARD SUPPLY | B2: 0.01 | E2: 0.05 | H2: 0.18 | K2: 0.28 | N2: CESS
B3: AMT | C3: CGST | D3: SGST | E3: AMT | F3: CGST | G3: SGST | H3: AMT | I3: CGST | J3: SGST | K3: AMT | L3: CGST | M3: SGST | N3: AMT | O3: 0.12
A4: SALES | C4: =B4*B2/2 -> 0 | D4: =B4*B2/2 -> 0 | E4: ='NOV working'!E7-'NOV working'!H7 -> 10762650 | F4: =E4*E2/2 -> 269066.25 | G4: =E4*E2/2 -> 269066.25 | H4: 0 | I4: =H4*H2/2 -> 0 | J4: =H4*H2/2 -> 0 | K4: 0 | L4: =K4*K2/2 -> 0 | M4: =K4*K2/2 -> 0 | O4: =N4*O3 -> 0
A5: ADVANCE | B5: ='NOV working'!E17 -> 455100 | C5: =+B5*B2/2 -> 2275.5 | D5: =+B5*B2/2 -> 2275.5 | E5: 0 | F5: =E5*E2/2 -> 0 | G5: =E5*E2/2 -> 0 | L5: =K5*K2/2 -> 0 | M5: =K5*K2/2 -> 0 | O5: =N5*O3 -> 0
